Workbook

Sheet Varsayımlar
A1: 2026 kazanç defteri — varsayımlar
A3: Başlangıç bakiyesi (1 Ocak 2026, $) | B3: 2000 | C3: ← değiştirilebilir (bu sayfadaki getiriler 2000 $ seviyesinin evreniyle ölçüldü)
A5: Kaynak: binance-carry-bot backtest motoru (g33.py), KAR_HARITASI madde 601 / 623 / 628 / 629. Günlük getiriler 'Günlük' sayfasında (mavi = motor çıktısı).
A6: Model: gerçekçi (canlı gibi tek hesap girişi + işlem başı 5 bp + düzeltilmiş kademe dolumu), iki dilim hizasının ortalaması. Evren: D8 (2.000 $; PDF defterleriyle AYNI seri).
A7: T4 = kod varsayılanı, kaldıraçsız. T7K 1,15x: günlük getiri × kaldıraç (T4 ile aynı 6 yıllık maks düşüş, madde 596 yöntemi).
A8: Koşullu stop = CARRY_LONG_24S_PIYASA=0,03 (24 sa long stop yalnız piyasa medyanı ≤ −%3 iken). Bot ritminde (8 sa'te bir kontrol). 'Eski stop' = borsada koşulsuz 24 sa stop.
A9: Kâr her gün yeniden yatırılır (bileşik). 2026 ölçümü 1 Ocak – 30 Eylül (Ekim verisi henüz yok).
A10: Bunlar geçmiş verinin simülasyonudur; canlı hesabın gerçek sonucu değildir ve gelecek için garanti vermez.

Sheet Özet
A1: 2026 (1 Ocak – 30 Eylül) özet — 2.000 $ (D8)
A3: Ölçü | B3: T4 (şimdiki) | C3: T7K 1,15x + koşullu stop | D3: T7K 1,15x eski stop | E3: Eski bot T1 | F3: T6 1x + koşullu stop (bilgi)
A4: Başlangıç bakiyesi $ | B4: =Varsayımlar!$B$3 -> 2000 | C4: =Varsayımlar!$B$3 -> 2000 | D4: =Varsayımlar!$B$3 -> 2000 | E4: =Varsayımlar!$B$3 -> 2000 | F4: =Varsayımlar!$B$3 -> 2000
A5: 30 Eylül bakiyesi $ | B5: =Günlük!H274 -> 7678.7192 | C5: =Günlük!I274 -> 9280.7046 | D5: =Günlük!J274 -> 8711.7594 | E5: =Günlük!K274 -> 6272.4669 | F5: =Günlük!L274 -> 9823.0349
A6: Toplam kâr $ | B6: =Günlük!H274-Varsayımlar!$B$3 -> 5678.7192 | C6: =Günlük!I274-Varsayımlar!$B$3 -> 7280.7046 | D6: =Günlük!J274-Varsayımlar!$B$3 -> 6711.7594 | E6: =Günlük!K274-Varsayımlar!$B$3 -> 4272.4669 | F6: =Günlük!L274-Varsayımlar!$B$3 -> 7823.0349
A7: Toplam getiri % | B7: =Günlük!H274/Varsayımlar!$B$3-1 -> 2.8393596 | C7: =Günlük!I274/Varsayımlar!$B$3-1 -> 3.6403523 | D7: =Günlük!J274/Varsayımlar!$B$3-1 -> 3.3558797 | E7: =Günlük!K274/Varsayımlar!$B$3-1 -> 2.1362335 | F7: =Günlük!L274/Varsayımlar!$B$3-1 -> 3.9115174
A8: Ortalama günlük getiri % | B8: =AVERAGE(Günlük!C2:C274) -> 0.0051607119 | C8: =AVERAGE(Günlük!D2:D274) -> 0.0058986181 | D8: =AVERAGE(Günlük!E2:E274) -> 0.0056504621 | E8: =AVERAGE(Günlük!F2:F274) -> 0.004411001 | F8: =AVERAGE(Günlük!G2:G274) -> 0.0061117478
A9: En iyi gün % | B9: =MAX(Günlük!C2:C274) -> 0.07957739 | C9: =MAX(Günlük!D2:D274) -> 0.090146665 | D9: =MAX(Günlük!E2:E274) -> 0.089828306 | E9: =MAX(Günlük!F2:F274) -> 0.070802855 | F9: =MAX(Günlük!G2:G274) -> 0.079187361
A10: En kötü gün % | B10: =MIN(Günlük!C2:C274) -> -0.046857989 | C10: =MIN(Günlük!D2:D274) -> -0.060334453 | D10: =MIN(Günlük!E2:E274) -> -0.049488657 | E10: =MIN(Günlük!F2:F274) -> -0.053418702 | F10: =MIN(Günlük!G2:G274) -> -0.05061617
A11: Kazançlı gün sayısı | B11: =COUNTIF(Günlük!C2:C274,">0") -> 153 | C11: =COUNTIF(Günlük!D2:D274,">0") -> 164 | D11: =COUNTIF(Günlük!E2:E274,">0") -> 158 | E11: =COUNTIF(Günlük!F2:F274,">0") -> 157 | F11: =COUNTIF(Günlük!G2:G274,">0") -> 165
A12: Zararlı gün sayısı | B12: =COUNTIF(Günlük!C2:C274,"<0") -> 120 | C12: =COUNTIF(Günlük!D2:D274,"<0") -> 109 | D12: =COUNTIF(Günlük!E2:E274,"<0") -> 115 | E12: =COUNTIF(Günlük!F2:F274,"<0") -> 116 | F12: =COUNTIF(Günlük!G2:G274,"<0") -> 108
A13: −%3'ten kötü gün | B13: =COUNTIF(Günlük!C2:C274,"<-0.03") -> 11 | C13: =COUNTIF(Günlük!D2:D274,"<-0.03") -> 15 | D13: =COUNTIF(Günlük!E2:E274,"<-0.03") -> 12 | E13: =COUNTIF(Günlük!F2:F274,"<-0.03") -> 12 | F13: =COUNTIF(Günlük!G2:G274,"<-0.03") -> 18
A14: −%5'ten kötü gün | B14: =COUNTIF(Günlük!C2:C274,"<-0.05") -> 0 | C14: =COUNTIF(Günlük!D2:D274,"<-0.05") -> 2 | D14: =COUNTIF(Günlük!E2:E274,"<-0.05") -> 0 | E14: =COUNTIF(Günlük!F2:F274,"<-0.05") -> 1 | F14: =COUNTIF(Günlük!G2:G274,"<-0.05") -> 1
A15: En kötü hafta % | B15: =MIN(Haftalık!E2:E41) -> -0.080492329 | C15: =MIN(Haftalık!F2:F41) -> -0.094508168 | D15: =MIN(Haftalık!G2:G41) -> -0.083947833 | E15: =MIN(Haftalık!H2:H41) -> -0.10573005 | F15: =MIN(Haftalık!I2:I41) -> -0.10549922
A16: En kötü ay % | B16: =MIN(Aylık!E2:E10) -> 0.02819021 | C16: =MIN(Aylık!F2:F10) -> 0.0090666083 | D16: =MIN(Aylık!G2:G10) -> 0.021348364 | E16: =MIN(Aylık!H2:H10) -> -0.026734206 | F16: =MIN(Aylık!I2:I10) -> 0.01620786
A17: Zararlı hafta sayısı | B17: =COUNTIF(Haftalık!E2:E41,"<0") -> 11 | C17: =COUNTIF(Haftalık!F2:F41,"<0") -> 10 | D17: =COUNTIF(Haftalık!G2:G41,"<0") -> 11 | E17: =COUNTIF(Haftalık!H2:H41,"<0") -> 11 | F17: =COUNTIF(Haftalık!I2:I41,"<0") -> 11

Sheet Günlük
A1: Tarih | B1: Gün | C1: T4 (şimdiki) günlük % | D1: T7K 1,15x + koşullu stop günlük % | E1: T7K 1,15x eski stop günlük % | F1: Eski bot T1 günlük % | G1: T6 1x + koşullu stop (bilgi) günlük % | H1: T4 (şimdiki) bakiye $ | I1: T7K 1,15x + koşullu stop bakiye $ | J1: T7K 1,15x eski stop bakiye $ | K1: Eski bot T1 bakiye $ | L1: T6 1x + koşullu stop (bilgi) bakiye $ | M1: T4 (şimdiki) günlük kâr $ | N1: T7K 1,15x + koşullu stop günlük kâr $ | O1: T7K 1,15x eski stop günlük kâr $ | P1: Eski bot T1 günlük kâr $ | Q1: T6 1x + koşullu stop (bilgi) günlük kâr $
A2: 46023 | B2: Per | C2: -0.0084873373 | D2: -0.015058698 | E2: -0.016493895 | F2: -0.01467528 | G2: -0.015420854 | H2: =Varsayımlar!$B$3*(1+C2) -> 1983.0253 | I2: =Varsayımlar!$B$3*(1+D2) -> 1969.8826 | J2: =Varsayımlar!$B$3*(1+E2) -> 1967.0122 | K2: =Varsayımlar!$B$3*(1+F2) -> 1970.6494 | L2: =Varsayımlar!$B$3*(1+G2) -> 1969.1583 | M2: =H2-Varsayımlar!$B$3 -> -16.974675 | N2: =I2-Varsayımlar!$B$3 -> -30.117396 | O2: =J2-Varsayımlar!$B$3 -> -32.987791 | P2: =K2-Varsayımlar!$B$3 -> -29.35056 | Q2: =L2-Varsayımlar!$B$3 -> -30.841708
A3: 46024 | B3: Cum | C3: -0.022143518 | D3: -0.032705324 | E3: -0.033065897 | F3: -0.020358446 | G3: -0.032737763 | H3: =H2*(1+C3) -> 1939.1142 | I3: =I2*(1+D3) -> 1905.457 | J3: =J2*(1+E3) -> 1901.9712 | K3: =K2*(1+F3) -> 1930.5301 | L3: =L2*(1+G3) -> 1904.6925 | M3: =H3-H2 -> -43.911158 | N3: =I3-I2 -> -64.425648 | O3: =J3-J2 -> -65.041024 | P3: =K3-K2 -> -40.11936 | Q3: =L3-L2 -> -64.465838
A4: 46025 | B4: Cmt | C4: 0.0028466492 | D4: 0.00054549042 | E4: 0.0015030529 | F4: -0.000773296 | G4: 0.00057816519 | H4: =H3*(1+C4) -> 1944.6341 | I4: =I3*(1+D4) -> 1906.4964 | J4: =J3*(1+E4) -> 1904.8299 | K4: =K3*(1+F4) -> 1929.0372 | L4: =L3*(1+G4) -> 1905.7937 | M4: =H4-H3 -> 5.5199778 | N4: =I4-I3 -> 1.0394085 | O4: =J4-J3 -> 2.8587633 | P4: =K4-K3 -> -1.4928712 | Q4: =L4-L3 -> 1.1012269
A5: 46026 | B5: Paz | C5: 0.0057367919 | D5: 0.012222771 | E5: 0.01211791 | F5: 0.00054221496 | G5: 0.0088272659 | H5: =H4*(1+C5) -> 1955.7901 | I5: =I4*(1+D5) -> 1929.799 | J5: =J4*(1+E5) -> 1927.9125 | K5: =K4*(1+F5) -> 1930.0832 | L5: =L4*(1+G5) -> 1922.6166 | M5: =H5-H4 -> 11.155962 | N5: =I5-I4 -> 23.302668 | O5: =J5-J4 -> 23.082558 | P5: =K5-K4 -> 1.0459528 | Q5: =L5-L4 -> 16.822948
A6: 46027 | B6: Pzt | C6: 0.021854611 | D6: 0.021897789 | E6: 0.022006623 | F6: 0.025566088 | G6: 0.017649112 | H6: =H5*(1+C6) -> 1998.5331 | I6: =I5*(1+D6) -> 1972.0574 | J6: =J5*(1+E6) -> 1970.3394 | K6: =K5*(1+F6) -> 1979.4278 | L6: =L5*(1+G6) -> 1956.5491 | M6: =H6-H5 -> 42.743032 | N6: =I6-I5 -> 42.258333 | O6: =J6-J5 -> 42.426844 | P6: =K6-K5 -> 49.344676 | Q6: =L6-L5 -> 33.932476
A7: 46028 | B7: Sal | C7: 0.041174175 | D7: 0.046811815 | E7: 0.046869928 | F7: 0.042531702 | G7: 0.03950562 | H7: =H6*(1+C7) -> 2080.8211 | I7: =I6*(1+D7) -> 2064.3729 | J7: =J6*(1+E7) -> 2062.689 | K7: =K6*(1+F7) -> 2063.6163 | L7: =L6*(1+G7) -> 2033.8438 | M7: =H7-H6 -> 82.287953 | N7: =I7-I6 -> 92.315585 | O7: =J7-J6 -> 92.349663 | P7: =K7-K6 -> 84.188436 | Q7: =L7-L6 -> 77.294685
A8: 46029 | B8: Çar | C8: -0.0019117697 | D8: 0.00044940332 | E8: 0.00044929952 | F8: 0.0064255178 | G8: 0.006525783 | H8: =H7*(1+C8) -> 2076.843 | I8: =I7*(1+D8) -> 2065.3007 | J8: =J7*(1+E8) -> 2063.6158 | K8: =K7*(1+F8) -> 2076.8761 | L8: =L7*(1+G8) -> 2047.1162 | M8: =H8-H7 -> -3.9780508 | N8: =I8-I7 -> 0.92773606 | O8: =J8-J7 -> 0.92676518 | P8: =K8-K7 -> 13.259803 | Q8: =L8-L7 -> 13.272423
A9: 46030 | B9: Per | C9: 0.011645644 | D9: 0.012587589 | E9: 0.012587533 | F9: 0.013994168 | G9: 0.015241206 | H9: =H8*(1+C9) -> 2101.0292 | I9: =I8*(1+D9) -> 2091.2978 | J9: =J8*(1+E9) -> 2089.5916 | K9: =K8*(1+F9) -> 2105.9402 | L9: =L8*(1+G9) -> 2078.3167 | M9: =H9-H8 -> 24.186174 | N9: =I9-I8 -> 25.997156 | O9: =J9-J8 -> 25.975832 | P9: =K9-K8 -> 29.064153 | Q9: =L9-L8 -> 31.200521
A10: 46031 | B10: Cum | C10: -0.0039665488 | D10: -0.0030602256 | E10: -0.0030600822 | F10: -0.0034434756 | G10: -0.002180695 | H10: =H9*(1+C10) -> 2092.6954 | I10: =I9*(1+D10) -> 2084.898 | J10: =J9*(1+E10) -> 2083.1973 | K10: =K9*(1+F10) -> 2098.6885 | L10: =L9*(1+G10) -> 2073.7846 | M10: =H10-H9 -> -8.333835 | N10: =I10-I9 -> -6.3998433 | O10: =J10-J9 -> -6.3943221 | P10: =K10-K9 -> -7.2517538 | Q10: =L10-L9 -> -4.532175
A11: 46032 | B11: Cmt | C11: -0.00011060844 | D11: -0.0027123882 | E11: -0.0027126182 | F11: -0.0065327524 | G11: -0.0020444167 | H11: =H10*(1+C11) -> 2092.4639 | I11: =I10*(1+D11) -> 2079.2429 | J11: =J10*(1+E11) -> 2077.5464 | K11: =K10*(1+F11) -> 2084.9783 | L11: =L10*(1+G11) -> 2069.5449 | M11: =H11-H10 -> -0.23146977 | N11: =I11-I10 -> -5.6550528 | O11: =J11-J10 -> -5.650919 | P11: =K11-K10 -> -13.710212 | Q11: =L11-L10 -> -4.2396798
A12: 46033 | B12: Paz | C12: 0.03012307 | D12: 0.03551892 | E12: 0.035519509 | F12: 0.034717386 | G12: 0.031164554 | H12: =H11*(1+C12) -> 2155.4953 | I12: =I11*(1+D12) -> 2153.0954 | J12: =J11*(1+E12) -> 2151.3398 | K12: =K11*(1+F12) -> 2157.3633 | L12: =L11*(1+G12) -> 2134.0413 | M12: =H12-H11 -> 63.031437 | N12: =I12-I11 -> 73.852463 | O12: =J12-J11 -> 73.793427 | P12: =K12-K11 -> 72.384995 | Q12: =L12-L11 -> 64.496443
A13: 46034 | B13: Pzt | C13: 0.0111307 | D13: 0.013730028 | E13: 0.013730131 | F13: 0.013022553 | G13: 0.014563968 | H13: =H12*(1+C13) -> 2179.4875 | I13: =I12*(1+D13) -> 2182.6575 | J13: =J12*(1+E13) -> 2180.878 | K13: =K12*(1+F13) -> 2185.4576 | L13: =L12*(1+G13) -> 2165.1214 | M13: =H13-H12 -> 23.992173 | N13: =I13-I12 -> 29.562061 | O13: =J13-J12 -> 29.538176 | P13: =K13-K12 -> 28.094377 | Q13: =L13-L12 -> 31.08011
A14: 46035 | B14: Sal | C14: 0.0090172394 | D14: 0.0081178404 | E14: 0.008121669 | F14: -0.00054375991 | G14: -0.00079536984 | H14: =H13*(1+C14) -> 2199.1405 | I14: =I13*(1+D14) -> 2200.3759 | J14: =J13*(1+E14) -> 2198.5903 | K14: =K13*(1+F14) -> 2184.2693 | L14: =L13*(1+G14) -> 2163.3994 | M14: =H14-H13 -> 19.652961 | N14: =I14-I13 -> 17.718465 | O14: =J14-J13 -> 17.712369 | P14: =K14-K13 -> -1.1883642 | Q14: =L14-L13 -> -1.7220723
... A274: 46295 | B274: Çar | C274: -0.015004867 | D274: -0.0067421631 | E274: -0.0067421804 | F274: -0.010650893 | G274: -0.0085000106 | H274: =H273*(1+C274) -> 7678.7192 | I274: =I273*(1+D274) -> 9280.7046 | J274: =J273*(1+E274) -> 8711.7594 | K274: =K273*(1+F274) -> 6272.4669 | L274: =L273*(1+G274) -> 9823.0349 | M274: =H274-H273 -> -116.97333 | N274: =I274-I273 -> -62.996759 | O274: =J274-J273 -> -59.134952 | P274: =K274-K273 -> -67.526594 | Q274: =L274-L273 -> -84.2117

Sheet Haftalık
A1: Hafta | B1: Başlangıç | C1: Bitiş | D1: Gün | E1: T4 (şimdiki) getiri % | F1: T7K 1,15x + koşullu stop getiri % | G1: T7K 1,15x eski stop getiri % | H1: Eski bot T1 getiri % | I1: T6 1x + koşullu stop (bilgi) getiri % | J1: T4 (şimdiki) kâr $ | K1: T7K 1,15x + koşullu stop kâr $ | L1: T7K 1,15x eski stop kâr $ | M1: Eski bot T1 kâr $ | N1: T6 1x + koşullu stop (bilgi) kâr $ | O1: T4 (şimdiki) dönem sonu bakiye $ | P1: T7K 1,15x + koşullu stop dönem sonu bakiye $ | Q1: T7K 1,15x eski stop dönem sonu bakiye $ | R1: Eski bot T1 dönem sonu bakiye $ | S1: T6 1x + koşullu stop (bilgi) dönem sonu bakiye $
A2: 29.12 haftası | B2: =Günlük!A2 -> 46023 | C2: =Günlük!A5 -> 46026 | D2: 4 | E2: =Günlük!H5/Varsayımlar!$B$3-1 -> -0.022104947 | F2: =Günlük!I5/Varsayımlar!$B$3-1 -> -0.035100484 | G2: =Günlük!J5/Varsayımlar!$B$3-1 -> -0.036043746 | H2: =Günlük!K5/Varsayımlar!$B$3-1 -> -0.034958419 | I2: =Günlük!L5/Varsayımlar!$B$3-1 -> -0.038691686 | J2: =Günlük!H5-Varsayımlar!$B$3 -> -44.209893 | K2: =Günlük!I5-Varsayımlar!$B$3 -> -70.200967 | L2: =Günlük!J5-Varsayımlar!$B$3 -> -72.087492 | M2: =Günlük!K5-Varsayımlar!$B$3 -> -69.916838 | N2: =Günlük!L5-Varsayımlar!$B$3 -> -77.383371 | O2: =Günlük!H5 -> 1955.7901 | P2: =Günlük!I5 -> 1929.799 | Q2: =Günlük!J5 -> 1927.9125 | R2: =Günlük!K5 -> 1930.0832 | S2: =Günlük!L5 -> 1922.6166
A3: 05.01 haftası | B3: =Günlük!A6 -> 46027 | C3: =Günlük!A12 -> 46033 | D3: 7 | E3: =Günlük!H12/Günlük!H5-1 -> 0.10210975 | F3: =Günlük!I12/Günlük!I5-1 -> 0.11570965 | G3: =Günlük!J12/Günlük!J5-1 -> 0.11589078 | H3: =Günlük!K12/Günlük!K5-1 -> 0.11775663 | I3: =Günlük!L12/Günlük!L5-1 -> 0.10996716 | J3: =Günlük!H12-Günlük!H5 -> 199.70524 | K3: =Günlük!I12-Günlük!I5 -> 223.29638 | L3: =Günlük!J12-Günlük!J5 -> 223.42729 | M3: =Günlük!K12-Günlük!K5 -> 227.2801 | N3: =Günlük!L12-Günlük!L5 -> 211.42469 | O3: =Günlük!H12 -> 2155.4953 | P3: =Günlük!I12 -> 2153.0954 | Q3: =Günlük!J12 -> 2151.3398 | R3: =Günlük!K12 -> 2157.3633 | S3: =Günlük!L12 -> 2134.0413
A4: 12.01 haftası | B4: =Günlük!A13 -> 46034 | C4: =Günlük!A19 -> 46040 | D4: 7 | E4: =Günlük!H19/Günlük!H12-1 -> 0.1089314 | F4: =Günlük!I19/Günlük!I12-1 -> 0.11762831 | G4: =Günlük!J19/Günlük!J12-1 -> 0.11767114 | H4: =Günlük!K19/Günlük!K12-1 -> 0.098485929 | I4: =Günlük!L19/Günlük!L12-1 -> 0.10212804 | J4: =Günlük!H19-Günlük!H12 -> 234.80113 | K4: =Günlük!I19-Günlük!I12 -> 253.26498 | L4: =Günlük!J19-Günlük!J12 -> 253.1506 | M4: =Günlük!K19-Günlük!K12 -> 212.46993 | N4: =Günlük!L19-Günlük!L12 -> 217.94546 | O4: =Günlük!H19 -> 2390.2965 | P4: =Günlük!I19 -> 2406.3604 | Q4: =Günlük!J19 -> 2404.4904 | R4: =Günlük!K19 -> 2369.8332 | S4: =Günlük!L19 -> 2351.9868
A5: 19.01 haftası | B5: =Günlük!A20 -> 46041 | C5: =Günlük!A26 -> 46047 | D5: 7 | E5: =Günlük!H26/Günlük!H19-1 -> 0.17235283 | F5: =Günlük!I26/Günlük!I19-1 -> 0.15790705 | G5: =Günlük!J26/Günlük!J19-1 -> 0.15811882 | H5: =Günlük!K26/Günlük!K19-1 -> 0.16937075 | I5: =Günlük!L26/Günlük!L19-1 -> 0.14966327 | J5: =Günlük!H26-Günlük!H19 -> 411.97437 | K5: =Günlük!I26-Günlük!I19 -> 379.98126 | L5: =Günlük!J26-Günlük!J19 -> 380.19519 | M5: =Günlük!K26-Günlük!K19 -> 401.38043 | N5: =Günlük!L26-Günlük!L19 -> 352.00604 | O5: =Günlük!H26 -> 2802.2708 | P5: =Günlük!I26 -> 2786.3416 | Q5: =Günlük!J26 -> 2784.6856 | R5: =Günlük!K26 -> 2771.2136 | S5: =Günlük!L26 -> 2703.9928
A6: 26.01 haftası | B6: =Günlük!A27 -> 46048 | C6: =Günlük!A33 -> 46054 | D6: 7 | E6: =Günlük!H33/Günlük!H26-1 -> 0.0059282511 | F6: =Günlük!I33/Günlük!I26-1 -> -0.0025297587 | G6: =Günlük!J33/Günlük!J26-1 -> -0.011511675 | H6: =Günlük!K33/Günlük!K26-1 -> -0.024088002 | I6: =Günlük!L33/Günlük!L26-1 -> 0.018061135 | J6: =Günlük!H33-Günlük!H26 -> 16.612565 | K6: =Günlük!I33-Günlük!I26 -> -7.0487721 | L6: =Günlük!J33-Günlük!J26 -> -32.056396 | M6: =Günlük!K33-Günlük!K26 -> -66.752999 | N6: =Günlük!L33-Günlük!L26 -> 48.837181 | O6: =Günlük!H33 -> 2818.8834 | P6: =Günlük!I33 -> 2779.2929 | Q6: =Günlük!J33 -> 2752.6292 | R6: =Günlük!K33 -> 2704.4606 | S6: =Günlük!L33 -> 2752.83
A7: 02.02 haftası | B7: =Günlük!A34 -> 46055 | C7: =Günlük!A40 -> 46061 | D7: 7 | E7: =Günlük!H40/Günlük!H33-1 -> 0.025237161 | F7: =Günlük!I40/Günlük!I33-1 -> 0.045492835 | G7: =Günlük!J40/Günlük!J33-1 -> 0.045674932 | H7: =Günlük!K40/Günlük!K33-1 -> 0.038443935 | I7: =Günlük!L40/Günlük!L33-1 -> 0.052805963 | J7: =Günlük!H40-Günlük!H33 -> 71.140615 | K7: =Günlük!I40-Günlük!I33 -> 126.43791 | L7: =Günlük!J40-Günlük!J33 -> 125.72615 | M7: =Günlük!K40-Günlük!K33 -> 103.97011 | N7: =Günlük!L40-Günlük!L33 -> 145.36584 | O7: =Günlük!H40 -> 2890.024 | P7: =Günlük!I40 -> 2905.7308 | Q7: =Günlük!J40 -> 2878.3553 | R7: =Günlük!K40 -> 2808.4307 | S7: =Günlük!L40 -> 2898.1958
A8: 09.02 haftası | B8: =Günlük!A41 -> 46062 | C8: =Günlük!A47 -> 46068 | D8: 7 | E8: =Günlük!H47/Günlük!H40-1 -> 0.029958314 | F8: =Günlük!I47/Günlük!I40-1 -> 0.037899826 | G8: =Günlük!J47/Günlük!J40-1 -> 0.039432303 | H8: =Günlük!K47/Günlük!K40-1 -> 0.017955797 | I8: =Günlük!L47/Günlük!L40-1 -> 0.024517723 | J8: =Günlük!H47-Günlük!H40 -> 86.580247 | K8: =Günlük!I47-Günlük!I40 -> 110.12669 | L8: =Günlük!J47-Günlük!J40 -> 113.50018 | M8: =Günlük!K47-Günlük!K40 -> 50.427612 | N8: =Günlük!L47-Günlük!L40 -> 71.057163 | O8: =Günlük!H47 -> 2976.6043 | P8: =Günlük!I47 -> 3015.8575 | Q8: =Günlük!J47 -> 2991.8555 | R8: =Günlük!K47 -> 2858.8583 | S8: =Günlük!L47 -> 2969.253
A9: 16.02 haftası | B9: =Günlük!A48 -> 46069 | C9: =Günlük!A54 -> 46075 | D9: 7 | E9: =Günlük!H54/Günlük!H47-1 -> -0.0092022207 | F9: =Günlük!I54/Günlük!I47-1 -> 0.00048229892 | G9: =Günlük!J54/Günlük!J47-1 -> -0.010820656 | H9: =Günlük!K54/Günlük!K47-1 -> 0.011782933 | I9: =Günlük!L54/Günlük!L47-1 -> -0.00345089 | J9: =Günlük!H54-Günlük!H47 -> -27.391369 | K9: =Günlük!I54-Günlük!I47 -> 1.4545448 | L9: =Günlük!J54-Günlük!J47 -> -32.37384 | M9: =Günlük!K54-Günlük!K47 -> 33.685735 | N9: =Günlük!L54-Günlük!L47 -> -10.246566 | O9: =Günlük!H54 -> 2949.2129 | P9: =Günlük!I54 -> 3017.312 | Q9: =Günlük!J54 -> 2959.4817 | R9: =Günlük!K54 -> 2892.5441 | S9: =Günlük!L54 -> 2959.0064
A10: 23.02 haftası | B10: =Günlük!A55 -> 46076 | C10: =Günlük!A61 -> 46082 | D10: 7 | E10: =Günlük!H61/Günlük!H54-1 -> 0.138478 | F10: =Günlük!I61/Günlük!I54-1 -> 0.15884235 | G10: =Günlük!J61/Günlük!J54-1 -> 0.15723474 | H10: =Günlük!K61/Günlük!K54-1 -> 0.12571102 | I10: =Günlük!L61/Günlük!L54-1 -> 0.15405932 | J10: =Günlük!H61-Günlük!H54 -> 408.40109 | K10: =Günlük!I61-Günlük!I54 -> 479.27694 | L10: =Günlük!J61-Günlük!J54 -> 465.33332 | M10: =Günlük!K61-Günlük!K54 -> 363.62466 | N10: =Günlük!L61-Günlük!L54 -> 455.86251 | O10: =Günlük!H61 -> 3357.614 | P10: =Günlük!I61 -> 3496.589 | Q10: =Günlük!J61 -> 3424.815 | R10: =Günlük!K61 -> 3256.1687 | S10: =Günlük!L61 -> 3414.869
A11: 02.03 haftası | B11: =Günlük!A62 -> 46083 | C11: =Günlük!A68 -> 46089 | D11: 7 | E11: =Günlük!H68/Günlük!H61-1 -> 0.061935551 | F11: =Günlük!I68/Günlük!I61-1 -> 0.049030952 | G11: =Günlük!J68/Günlük!J61-1 -> 0.062529144 | H11: =Günlük!K68/Günlük!K61-1 -> 0.054252246 | I11: =Günlük!L68/Günlük!L61-1 -> 0.050615735 | J11: =Günlük!H68-Günlük!H61 -> 207.95567 | K11: =Günlük!I68-Günlük!I61 -> 171.44109 | L11: =Günlük!J68-Günlük!J61 -> 214.15075 | M11: =Günlük!K68-Günlük!K61 -> 176.65447 | N11: =Günlük!L68-Günlük!L61 -> 172.8461 | O11: =Günlük!H68 -> 3565.5697 | P11: =Günlük!I68 -> 3668.0301 | Q11: =Günlük!J68 -> 3638.9658 | R11: =Günlük!K68 -> 3432.8232 | S11: =Günlük!L68 -> 3587.7151
A12: 09.03 haftası | B12: =Günlük!A69 -> 46090 | C12: =Günlük!A75 -> 46096 | D12: 7 | E12: =Günlük!H75/Günlük!H68-1 -> -0.047643116 | F12: =Günlük!I75/Günlük!I68-1 -> -0.062885258 | G12: =Günlük!J75/Günlük!J68-1 -> -0.055340049 | H12: =Günlük!K75/Günlük!K68-1 -> -0.050733791 | I12: =Günlük!L75/Günlük!L68-1 -> -0.058251784 | J12: =Günlük!H75-Günlük!H68 -> -169.87485 | K12: =Günlük!I75-Günlük!I68 -> -230.66502 | L12: =Günlük!J75-Günlük!J68 -> -201.38055 | M12: =Günlük!K75-Günlük!K68 -> -174.16013 | N12: =Günlük!L75-Günlük!L68 -> -208.9908 | O12: =Günlük!H75 -> 3395.6948 | P12: =Günlük!I75 -> 3437.365 | Q12: =Günlük!J75 -> 3437.5852 | R12: =Günlük!K75 -> 3258.6631 | S12: =Günlük!L75 -> 3378.7243
A13: 16.03 haftası | B13: =Günlük!A76 -> 46097 | C13: =Günlük!A82 -> 46103 | D13: 7 | E13: =Günlük!H82/Günlük!H75-1 -> 0.15213496 | F13: =Günlük!I82/Günlük!I75-1 -> 0.14297151 | G13: =Günlük!J82/Günlük!J75-1 -> 0.17109711 | H13: =Günlük!K82/Günlük!K75-1 -> 0.14325744 | I13: =Günlük!L82/Günlük!L75-1 -> 0.13391929 | J13: =Günlük!H82-Günlük!H75 -> 516.6039 | K13: =Günlük!I82-Günlük!I75 -> 491.44527 | L13: =Günlük!J82-Günlük!J75 -> 588.1609 | M13: =Günlük!K82-Günlük!K75 -> 466.82773 | N13: =Günlük!L82-Günlük!L75 -> 452.47637 | O13: =Günlük!H82 -> 3912.2987 | P13: =Günlük!I82 -> 3928.8103 | Q13: =Günlük!J82 -> 4025.7461 | R13: =Günlük!K82 -> 3725.4908 | S13: =Günlük!L82 -> 3831.2006
A14: 23.03 haftası | B14: =Günlük!A83 -> 46104 | C14: =Günlük!A89 -> 46110 | D14: 7 | E14: =Günlük!H89/Günlük!H82-1 -> -0.018287237 | F14: =Günlük!I89/Günlük!I82-1 -> 0.03277003 | G14: =Günlük!J89/Günlük!J82-1 -> -0.013699465 | H14: =Günlük!K89/Günlük!K82-1 -> -0.027497204 | I14: =Günlük!L89/Günlük!L82-1 -> 0.031517028 | J14: =Günlük!H89-Günlük!H82 -> -71.545133 | K14: =Günlük!I89-Günlük!I82 -> 128.74723 | L14: =Günlük!J89-Günlük!J82 -> -55.150567 | M14: =Günlük!K89-Günlük!K82 -> -102.44058 | N14: =Günlük!L89-Günlük!L82 -> 120.74806 | O14: =Günlük!H89 -> 3840.7536 | P14: =Günlük!I89 -> 4057.5575 | Q14: =Günlük!J89 -> 3970.5955 | R14: =Günlük!K89 -> 3623.0502 | S14: =Günlük!L89 -> 3951.9487
A15: 30.03 haftası | B15: =Günlük!A90 -> 46111 | C15: =Günlük!A96 -> 46117 | D15: 7 | E15: =Günlük!H96/Günlük!H89-1 -> -0.065140246 | F15: =Günlük!I96/Günlük!I89-1 -> -0.067085274 | G15: =Günlük!J96/Günlük!J89-1 -> -0.062160071 | H15: =Günlük!K96/Günlük!K89-1 -> 0.0031893088 | I15: =Günlük!L96/Günlük!L89-1 -> -0.067558128 | J15: =Günlük!H96-Günlük!H89 -> -250.18763 | K15: =Günlük!I96-Günlük!I89 -> -272.20236 | L15: =Günlük!J96-Günlük!J89 -> -246.8125 | M15: =Günlük!K96-Günlük!K89 -> 11.555026 | N15: =Günlük!L96-Günlük!L89 -> -266.98625 | O15: =Günlük!H96 -> 3590.566 | P15: =Günlük!I96 -> 3785.3552 | Q15: =Günlük!J96 -> 3723.783 | R15: =Günlük!K96 -> 3634.6052 | S15: =Günlük!L96 -> 3684.9624
A16: 06.04 haftası | B16: =Günlük!A97 -> 46118 | C16: =Günlük!A103 -> 46124 | D16: 7 | E16: =Günlük!H103/Günlük!H96-1 -> 0.00970146 | F16: =Günlük!I103/Günlük!I96-1 -> 0.090568886 | G16: =Günlük!J103/Günlük!J96-1 -> 0.023846854 | H16: =Günlük!K103/Günlük!K96-1 -> 0.018013702 | I16: =Günlük!L103/Günlük!L96-1 -> 0.079343961 | J16: =Günlük!H103-Günlük!H96 -> 34.833732 | K16: =Günlük!I103-Günlük!I96 -> 342.8354 | L16: =Günlük!J103-Günlük!J96 -> 88.80051 | M16: =Günlük!K103-Günlük!K96 -> 65.472697 | N16: =Günlük!L103-Günlük!L96 -> 292.37952 | O16: =Günlük!H103 -> 3625.3997 | P16: =Günlük!I103 -> 4128.1906 | Q16: =Günlük!J103 -> 3812.5836 | R16: =Günlük!K103 -> 3700.0779 | S16: =Günlük!L103 -> 3977.3419
A17: 13.04 haftası | B17: =Günlük!A104 -> 46125 | C17: =Günlük!A110 -> 46131 | D17: 7 | E17: =Günlük!H110/Günlük!H103-1 -> 0.1591078 | F17: =Günlük!I110/Günlük!I103-1 -> 0.15365501 | G17: =Günlük!J110/Günlük!J103-1 -> 0.18969129 | H17: =Günlük!K110/Günlük!K103-1 -> 0.087557465 | I17: =Günlük!L110/Günlük!L103-1 -> 0.13717154 | J17: =Günlük!H110-Günlük!H103 -> 576.82938 | K17: =Günlük!I110-Günlük!I103 -> 634.31718 | L17: =Günlük!J110-Günlük!J103 -> 723.21389 | M17: =Günlük!K110-Günlük!K103 -> 323.96944 | N17: =Günlük!L110-Günlük!L103 -> 545.57811 | O17: =Günlük!H110 -> 4202.2291 | P17: =Günlük!I110 -> 4762.5078 | Q17: =Günlük!J110 -> 4535.7974 | R17: =Günlük!K110 -> 4024.0474 | S17: =Günlük!L110 -> 4522.9201
A18: 20.04 haftası | B18: =Günlük!A111 -> 46132 | C18: =Günlük!A117 -> 46138 | D18: 7 | E18: =Günlük!H117/Günlük!H110-1 -> 0.030759306 | F18: =Günlük!I117/Günlük!I110-1 -> 0.031607748 | G18: =Günlük!J117/Günlük!J110-1 -> 0.031527535 | H18: =Günlük!K117/Günlük!K110-1 -> 0.002173373 | I18: =Günlük!L117/Günlük!L110-1 -> 0.0321123 | J18: =Günlük!H117-Günlük!H110 -> 129.25765 | K18: =Günlük!I117-Günlük!I110 -> 150.53214 | L18: =Günlük!J117-Günlük!J110 -> 143.00251 | M18: =Günlük!K117-Günlük!K110 -> 8.7457561 | N18: =Günlük!L117-Günlük!L110 -> 145.24137 | O18: =Günlük!H117 -> 4331.4867 | P18: =Günlük!I117 -> 4913.0399 | Q18: =Günlük!J117 -> 4678.8 | R18: =Günlük!K117 -> 4032.7931 | S18: =Günlük!L117 -> 4668.1614
A19: 27.04 haftası | B19: =Günlük!A118 -> 46139 | C19: =Günlük!A124 -> 46145 | D19: 7 | E19: =Günlük!H124/Günlük!H117-1 -> 0.093562413 | F19: =Günlük!I124/Günlük!I117-1 -> 0.11358103 | G19: =Günlük!J124/Günlük!J117-1 -> 0.11357077 | H19: =Günlük!K124/Günlük!K117-1 -> 0.084729236 | I19: =Günlük!L124/Günlük!L117-1 -> 0.10475567 | J19: =Günlük!H124-Günlük!H117 -> 405.26435 | K19: =Günlük!I124-Günlük!I117 -> 558.02815 | L19: =Günlük!J124-Günlük!J117 -> 531.3749 | M19: =Günlük!K124-Günlük!K117 -> 341.69548 | N19: =Günlük!L124-Günlük!L117 -> 489.01635 | O19: =Günlük!H124 -> 4736.7511 | P19: =Günlük!I124 -> 5471.0681 | Q19: =Günlük!J124 -> 5210.1749 | R19: =Günlük!K124 -> 4374.4886 | S19: =Günlük!L124 -> 5157.1778
A20: 04.05 haftası | B20: =Günlük!A125 -> 46146 | C20: =Günlük!A131 -> 46152 | D20: 7 | E20: =Günlük!H131/Günlük!H124-1 -> 0.069752494 | F20: =Günlük!I131/Günlük!I124-1 -> 0.065050301 | G20: =Günlük!J131/Günlük!J124-1 -> 0.065058689 | H20: =Günlük!K131/Günlük!K124-1 -> 0.029038337 | I20: =Günlük!L131/Günlük!L124-1 -> 0.050999326 | J20: =Günlük!H131-Günlük!H124 -> 330.4002 | K20: =Günlük!I131-Günlük!I124 -> 355.89462 | L20: =Günlük!J131-Günlük!J124 -> 338.96715 | M20: =Günlük!K131-Günlük!K124 -> 127.02787 | N20: =Günlük!L131-Günlük!L124 -> 263.01259 | O20: =Günlük!H131 -> 5067.1513 | P20: =Günlük!I131 -> 5826.9627 | Q20: =Günlük!J131 -> 5549.142 | R20: =Günlük!K131 -> 4501.5165 | S20: =Günlük!L131 -> 5420.1904
A21: 11.05 haftası | B21: =Günlük!A132 -> 46153 | C21: =Günlük!A138 -> 46159 | D21: 7 | E21: =Günlük!H138/Günlük!H131-1 -> -0.021069055 | F21: =Günlük!I138/Günlük!I131-1 -> -0.022158598 | G21: =Günlük!J138/Günlük!J131-1 -> -0.022158598 | H21: =Günlük!K138/Günlük!K131-1 -> -0.016543793 | I21: =Günlük!L138/Günlük!L131-1 -> -0.022661369 | J21: =Günlük!H138-Günlük!H131 -> -106.76009 | K21: =Günlük!I138-Günlük!I131 -> -129.11732 | L21: =Günlük!J138-Günlük!J131 -> -122.96121 | M21: =Günlük!K138-Günlük!K131 -> -74.472158 | N21: =Günlük!L138-Günlük!L131 -> -122.82894 | O21: =Günlük!H138 -> 4960.3912 | P21: =Günlük!I138 -> 5697.8454 | Q21: =Günlük!J138 -> 5426.1808 | R21: =Günlük!K138 -> 4427.0443 | S21: =Günlük!L138 -> 5297.3614
A22: 18.05 haftası | B22: =Günlük!A139 -> 46160 | C22: =Günlük!A145 -> 46166 | D22: 7 | E22: =Günlük!H145/Günlük!H138-1 -> 0.088167478 | F22: =Günlük!I145/Günlük!I138-1 -> 0.068824325 | G22: =Günlük!J145/Günlük!J138-1 -> 0.068824325 | H22: =Günlük!K145/Günlük!K138-1 -> 0.082301897 | I22: =Günlük!L145/Günlük!L138-1 -> 0.084041747 | J22: =Günlük!H145-Günlük!H138 -> 437.34518 | K22: =Günlük!I145-Günlük!I138 -> 392.15036 | L22: =Günlük!J145-Günlük!J138 -> 373.45323 | M22: =Günlük!K145-Günlük!K138 -> 364.35414 | N22: =Günlük!L145-Günlük!L138 -> 445.19951 | O22: =Günlük!H145 -> 5397.7364 | P22: =Günlük!I145 -> 6089.9957 | Q22: =Günlük!J145 -> 5799.634 | R22: =Günlük!K145 -> 4791.3985 | S22: =Günlük!L145 -> 5742.5609
A23: 25.05 haftası | B23: =Günlük!A146 -> 46167 | C23: =Günlük!A152 -> 46173 | D23: 7 | E23: =Günlük!H152/Günlük!H145-1 -> 0.016960694 | F23: =Günlük!I152/Günlük!I145-1 -> 0.02208665 | G23: =Günlük!J152/Günlük!J145-1 -> 0.02479696 | H23: =Günlük!K152/Günlük!K145-1 -> 0.0017761785 | I23: =Günlük!L152/Günlük!L145-1 -> 0.030133287 | J23: =Günlük!H152-Günlük!H145 -> 91.549356 | K23: =Günlük!I152-Günlük!I145 -> 134.50761 | L23: =Günlük!J152-Günlük!J145 -> 143.81329 | M23: =Günlük!K152-Günlük!K145 -> 8.5103791 | N23: =Günlük!L152-Günlük!L145 -> 173.04224 | O23: =Günlük!H152 -> 5489.2857 | P23: =Günlük!I152 -> 6224.5033 | Q23: =Günlük!J152 -> 5943.4473 | R23: =Günlük!K152 -> 4799.9089 | S23: =Günlük!L152 -> 5915.6032
A24: 01.06 haftası | B24: =Günlük!A153 -> 46174 | C24: =Günlük!A159 -> 46180 | D24: 7 | E24: =Günlük!H159/Günlük!H152-1 -> 0.023168065 | F24: =Günlük!I159/Günlük!I152-1 -> 0.065253467 | G24: =Günlük!J159/Günlük!J152-1 -> 0.038941398 | H24: =Günlük!K159/Günlük!K152-1 -> 0.0077372788 | I24: =Günlük!L159/Günlük!L152-1 -> 0.081089229 | J24: =Günlük!H159-Günlük!H152 -> 127.17613 | K24: =Günlük!I159-Günlük!I152 -> 406.17042 | L24: =Günlük!J159-Günlük!J152 -> 231.44615 | M24: =Günlük!K159-Günlük!K152 -> 37.138233 | N24: =Günlük!L159-Günlük!L152 -> 479.6917 | O24: =Günlük!H159 -> 5616.4618 | P24: =Günlük!I159 -> 6630.6737 | Q24: =Günlük!J159 -> 6174.8935 | R24: =Günlük!K159 -> 4837.0471 | S24: =Günlük!L159 -> 6395.2949
A25: 08.06 haftası | B25: =Günlük!A160 -> 46181 | C25: =Günlük!A166 -> 46187 | D25: 7 | E25: =Günlük!H166/Günlük!H159-1 -> -0.026832009 | F25: =Günlük!I166/Günlük!I159-1 -> -0.00099023634 | G25: =Günlük!J166/Günlük!J159-1 -> 0.0071347826 | H25: =Günlük!K166/Günlük!K159-1 -> -0.032830975 | I25: =Günlük!L166/Günlük!L159-1 -> -0.0010682196 | J25: =Günlük!H166-Günlük!H159 -> -150.70095 | K25: =Günlük!I166-Günlük!I159 -> -6.5659341 | L25: =Günlük!J166-Günlük!J159 -> 44.056522 | M25: =Günlük!K166-Günlük!K159 -> -158.80497 | N25: =Günlük!L166-Günlük!L159 -> -6.8315794 | O25: =Günlük!H166 -> 5465.7609 | P25: =Günlük!I166 -> 6624.1078 | Q25: =Günlük!J166 -> 6218.95 | R25: =Günlük!K166 -> 4678.2421 | S25: =Günlük!L166 -> 6388.4633
A26: 15.06 haftası | B26: =Günlük!A167 -> 46188 | C26: =Günlük!A173 -> 46194 | D26: 7 | E26: =Günlük!H173/Günlük!H166-1 -> 0.026006137 | F26: =Günlük!I173/Günlük!I166-1 -> 0.031011049 | G26: =Günlük!J173/Günlük!J166-1 -> 0.024260612 | H26: =Günlük!K173/Günlük!K166-1 -> 0.031265443 | I26: =Günlük!L173/Günlük!L166-1 -> 0.044991759 | J26: =Günlük!H173-Günlük!H166 -> 142.14333 | K26: =Günlük!I173-Günlük!I166 -> 205.42053 | L26: =Günlük!J173-Günlük!J166 -> 150.87553 | M26: =Günlük!K173-Günlük!K166 -> 146.26731 | N26: =Günlük!L173-Günlük!L166 -> 287.4282 | O26: =Günlük!H173 -> 5607.9042 | P26: =Günlük!I173 -> 6829.5283 | Q26: =Günlük!J173 -> 6369.8255 | R26: =Günlük!K173 -> 4824.5094 | S26: =Günlük!L173 -> 6675.8915
A27: 22.06 haftası | B27: =Günlük!A174 -> 46195 | C27: =Günlük!A180 -> 46201 | D27: 7 | E27: =Günlük!H180/Günlük!H173-1 -> 0.1105172 | F27: =Günlük!I180/Günlük!I173-1 -> 0.074142924 | G27: =Günlük!J180/Günlük!J173-1 -> 0.077804929 | H27: =Günlük!K180/Günlük!K173-1 -> 0.10008692 | I27: =Günlük!L180/Günlük!L173-1 -> 0.091647192 | J27: =Günlük!H180-Günlük!H173 -> 619.76985 | K27: =Günlük!I180-Günlük!I173 -> 506.3612 | L27: =Günlük!J180-Günlük!J173 -> 495.60382 | M27: =Günlük!K180-Günlük!K173 -> 482.87029 | N27: =Günlük!L180-Günlük!L173 -> 611.82671 | O27: =Günlük!H180 -> 6227.6741 | P27: =Günlük!I180 -> 7335.8895 | Q27: =Günlük!J180 -> 6865.4293 | R27: =Günlük!K180 -> 5307.3797 | S27: =Günlük!L180 -> 7287.7182
A28: 29.06 haftası | B28: =Günlük!A181 -> 46202 | C28: =Günlük!A187 -> 46208 | D28: 7 | E28: =Günlük!H187/Günlük!H180-1 -> 0.0078900255 | F28: =Günlük!I187/Günlük!I180-1 -> 0.044819916 | G28: =Günlük!J187/Günlük!J180-1 -> 0.013447094 | H28: =Günlük!K187/Günlük!K180-1 -> 0.0093860486 | I28: =Günlük!L187/Günlük!L180-1 -> 0.058275173 | J28: =Günlük!H187-Günlük!H180 -> 49.136507 | K28: =Günlük!I187-Günlük!I180 -> 328.79395 | L28: =Günlük!J187-Günlük!J180 -> 92.320071 | M28: =Günlük!K187-Günlük!K180 -> 49.815324 | N28: =Günlük!L187-Günlük!L180 -> 424.69304 | O28: =Günlük!H187 -> 6276.8106 | P28: =Günlük!I187 -> 7664.6835 | Q28: =Günlük!J187 -> 6957.7494 | R28: =Günlük!K187 -> 5357.195 | S28: =Günlük!L187 -> 7712.4112
A29: 06.07 haftası | B29: =Günlük!A188 -> 46209 | C29: =Günlük!A194 -> 46215 | D29: 7 | E29: =Günlük!H194/Günlük!H187-1 -> -0.015057852 | F29: =Günlük!I194/Günlük!I187-1 -> -0.041111181 | G29: =Günlük!J194/Günlük!J187-1 -> -0.019064538 | H29: =Günlük!K194/Günlük!K187-1 -> -0.018149725 | I29: =Günlük!L194/Günlük!L187-1 -> -0.042519343 | J29: =Günlük!H194-Günlük!H187 -> -94.515286 | K29: =Günlük!I194-Günlük!I187 -> -315.10419 | L29: =Günlük!J194-Günlük!J187 -> -132.64628 | M29: =Günlük!K194-Günlük!K187 -> -97.231617 | N29: =Günlük!L194-Günlük!L187 -> -327.92666 | O29: =Günlük!H194 -> 6182.2953 | P29: =Günlük!I194 -> 7349.5793 | Q29: =Günlük!J194 -> 6825.1031 | R29: =Günlük!K194 -> 5259.9634 | S29: =Günlük!L194 -> 7384.4846
A30: 13.07 haftası | B30: =Günlük!A195 -> 46216 | C30: =Günlük!A201 -> 46222 | D30: 7 | E30: =Günlük!H201/Günlük!H194-1 -> 0.069338521 | F30: =Günlük!I201/Günlük!I194-1 -> 0.049439942 | G30: =Günlük!J201/Günlük!J194-1 -> 0.051243847 | H30: =Günlük!K201/Günlük!K194-1 -> 0.027434802 | I30: =Günlük!L201/Günlük!L194-1 -> 0.061963985 | J30: =Günlük!H201-Günlük!H194 -> 428.67121 | K30: =Günlük!I201-Günlük!I194 -> 363.36278 | L30: =Günlük!J201-Günlük!J194 -> 349.74454 | M30: =Günlük!K201-Günlük!K194 -> 144.30605 | N30: =Günlük!L201-Günlük!L194 -> 457.57209 | O30: =Günlük!H201 -> 6610.9665 | P30: =Günlük!I201 -> 7712.9421 | Q30: =Günlük!J201 -> 7174.8477 | R30: =Günlük!K201 -> 5404.2695 | S30: =Günlük!L201 -> 7842.0567
A31: 20.07 haftası | B31: =Günlük!A202 -> 46223 | C31: =Günlük!A208 -> 46229 | D31: 7 | E31: =Günlük!H208/Günlük!H201-1 -> -0.0043753611 | F31: =Günlük!I208/Günlük!I201-1 -> 0.0015644382 | G31: =Günlük!J208/Günlük!J201-1 -> 0.0074214707 | H31: =Günlük!K208/Günlük!K201-1 -> -0.013069688 | I31: =Günlük!L208/Günlük!L201-1 -> -0.0016096206 | J31: =Günlük!H208-Günlük!H201 -> -28.925366 | K31: =Günlük!I208-Günlük!I201 -> 12.066422 | L31: =Günlük!J208-Günlük!J201 -> 53.247922 | M31: =Günlük!K208-Günlük!K201 -> -70.632118 | N31: =Günlük!L208-Günlük!L201 -> -12.622736 | O31: =Günlük!H208 -> 6582.0411 | P31: =Günlük!I208 -> 7725.0085 | Q31: =Günlük!J208 -> 7228.0956 | R31: =Günlük!K208 -> 5333.6374 | S31: =Günlük!L208 -> 7829.4339
A32: 27.07 haftası | B32: =Günlük!A209 -> 46230 | C32: =Günlük!A215 -> 46236 | D32: 7 | E32: =Günlük!H215/Günlük!H208-1 -> 0.026818046 | F32: =Günlük!I215/Günlük!I208-1 -> 0.014571476 | G32: =Günlük!J215/Günlük!J208-1 -> 0.028174403 | H32: =Günlük!K215/Günlük!K208-1 -> 0.031086825 | I32: =Günlük!L215/Günlük!L208-1 -> 0.010613632 | J32: =Günlük!H215-Günlük!H208 -> 176.51748 | K32: =Günlük!I215-Günlük!I208 -> 112.56477 | L32: =Günlük!J215-Günlük!J208 -> 203.64728 | M32: =Günlük!K215-Günlük!K208 -> 165.80585 | N32: =Günlük!L215-Günlük!L208 -> 83.098734 | O32: =Günlük!H215 -> 6758.5586 | P32: =Günlük!I215 -> 7837.5733 | Q32: =Günlük!J215 -> 7431.7429 | R32: =Günlük!K215 -> 5499.4432 | S32: =Günlük!L215 -> 7912.5327
A33: 03.08 haftası | B33: =Günlük!A216 -> 46237 | C33: =Günlük!A222 -> 46243 | D33: 7 | E33: =Günlük!H222/Günlük!H215-1 -> 0.072555615 | F33: =Günlük!I222/Günlük!I215-1 -> 0.047345817 | G33: =Günlük!J222/Günlük!J215-1 -> 0.049706154 | H33: =Günlük!K222/Günlük!K215-1 -> 0.068816149 | I33: =Günlük!L222/Günlük!L215-1 -> 0.042730526 | J33: =Günlük!H222-Günlük!H215 -> 490.37138 | K33: =Günlük!I222-Günlük!I215 -> 371.07631 | L33: =Günlük!J222-Günlük!J215 -> 369.40336 | M33: =Günlük!K222-Günlük!K215 -> 378.4505 | N33: =Günlük!L222-Günlük!L215 -> 338.10668 | O33: =Günlük!H222 -> 7248.93 | P33: =Günlük!I222 -> 8208.6496 | Q33: =Günlük!J222 -> 7801.1462 | R33: =Günlük!K222 -> 5877.8937 | S33: =Günlük!L222 -> 8250.6394
A34: 10.08 haftası | B34: =Günlük!A223 -> 46244 | C34: =Günlük!A229 -> 46250 | D34: 7 | E34: =Günlük!H229/Günlük!H222-1 -> -0.072583044 | F34: =Günlük!I229/Günlük!I222-1 -> -0.094508168 | G34: =Günlük!J229/Günlük!J222-1 -> -0.083947833 | H34: =Günlük!K229/Günlük!K222-1 -> -0.10573005 | I34: =Günlük!L229/Günlük!L222-1 -> -0.10549922 | J34: =Günlük!H229-Günlük!H222 -> -526.14941 | K34: =Günlük!I229-Günlük!I222 -> -775.78443 | L34: =Günlük!J229-Günlük!J222 -> -654.88932 | M34: =Günlük!K229-Günlük!K222 -> -621.47002 | N34: =Günlük!L229-Günlük!L222 -> -870.43603 | O34: =Günlük!H229 -> 6722.7806 | P34: =Günlük!I229 -> 7432.8652 | Q34: =Günlük!J229 -> 7146.2569 | R34: =Günlük!K229 -> 5256.4237 | S34: =Günlük!L229 -> 7380.2033
A35: 17.08 haftası | B35: =Günlük!A230 -> 46251 | C35: =Günlük!A236 -> 46257 | D35: 7 | E35: =Günlük!H236/Günlük!H229-1 -> 0.0022278899 | F35: =Günlük!I236/Günlük!I229-1 -> 0.049783783 | G35: =Günlük!J236/Günlük!J229-1 -> 0.024949239 | H35: =Günlük!K236/Günlük!K229-1 -> 0.043708875 | I35: =Günlük!L236/Günlük!L229-1 -> 0.064123322 | J35: =Günlük!H236-Günlük!H229 -> 14.977615 | K35: =Günlük!I236-Günlük!I229 -> 370.03615 | L35: =Günlük!J236-Günlük!J229 -> 178.29367 | M35: =Günlük!K236-Günlük!K229 -> 229.75237 | N35: =Günlük!L236-Günlük!L229 -> 473.24315 | O35: =Günlük!H236 -> 6737.7582 | P35: =Günlük!I236 -> 7802.9013 | Q35: =Günlük!J236 -> 7324.5506 | R35: =Günlük!K236 -> 5486.1761 | S35: =Günlük!L236 -> 7853.4465
A36: 24.08 haftası | B36: =Günlük!A237 -> 46258 | C36: =Günlük!A243 -> 46264 | D36: 7 | E36: =Günlük!H243/Günlük!H236-1 -> 0.096651896 | F36: =Günlük!I243/Günlük!I236-1 -> 0.10456305 | G36: =Günlük!J243/Günlük!J236-1 -> 0.10484382 | H36: =Günlük!K243/Günlük!K236-1 -> 0.10025474 | I36: =Günlük!L243/Günlük!L236-1 -> 0.12902243 | J36: =Günlük!H243-Günlük!H236 -> 651.21711 | K36: =Günlük!I243-Günlük!I236 -> 815.89515 | L36: =Günlük!J243-Günlük!J236 -> 767.93386 | M36: =Günlük!K243-Günlük!K236 -> 550.01517 | N36: =Günlük!L243-Günlük!L236 -> 1013.2708 | O36: =Günlük!H243 -> 7388.9753 | P36: =Günlük!I243 -> 8618.7965 | Q36: =Günlük!J243 -> 8092.4844 | R36: =Günlük!K243 -> 6036.1912 | S36: =Günlük!L243 -> 8866.7173
A37: 31.08 haftası | B37: =Günlük!A244 -> 46265 | C37: =Günlük!A250 -> 46271 | D37: 7 | E37: =Günlük!H250/Günlük!H243-1 -> 0.0042092284 | F37: =Günlük!I250/Günlük!I243-1 -> -0.0047892716 | G37: =Günlük!J250/Günlük!J243-1 -> -0.004790884 | H37: =Günlük!K250/Günlük!K243-1 -> -0.010852983 | I37: =Günlük!L250/Günlük!L243-1 -> -0.0085152579 | J37: =Günlük!H250-Günlük!H243 -> 31.101885 | K37: =Günlük!I250-Günlük!I243 -> -41.277757 | L37: =Günlük!J250-Günlük!J243 -> -38.770154 | M37: =Günlük!K250-Günlük!K243 -> -65.510678 | N37: =Günlük!L250-Günlük!L243 -> -75.502384 | O37: =Günlük!H250 -> 7420.0772 | P37: =Günlük!I250 -> 8577.5187 | Q37: =Günlük!J250 -> 8053.7143 | R37: =Günlük!K250 -> 5970.6806 | S37: =Günlük!L250 -> 8791.2149
A38: 07.09 haftası | B38: =Günlük!A251 -> 46272 | C38: =Günlük!A257 -> 46278 | D38: 7 | E38: =Günlük!H257/Günlük!H250-1 -> 0.082510749 | F38: =Günlük!I257/Günlük!I250-1 -> 0.074759577 | G38: =Günlük!J257/Günlük!J250-1 -> 0.076261872 | H38: =Günlük!K257/Günlük!K250-1 -> 0.068714578 | I38: =Günlük!L257/Günlük!L250-1 -> 0.094476697 | J38: =Günlük!H257-Günlük!H250 -> 612.23613 | K38: =Günlük!I257-Günlük!I250 -> 641.25167 | L38: =Günlük!J257-Günlük!J250 -> 614.19133 | M38: =Günlük!K257-Günlük!K250 -> 410.2728 | N38: =Günlük!L257-Günlük!L250 -> 830.56495 | O38: =Günlük!H257 -> 8032.3133 | P38: =Günlük!I257 -> 9218.7704 | Q38: =Günlük!J257 -> 8667.9056 | R38: =Günlük!K257 -> 6380.9534 | S38: =Günlük!L257 -> 9621.7798
A39: 14.09 haftası | B39: =Günlük!A258 -> 46279 | C39: =Günlük!A264 -> 46285 | D39: 7 | E39: =Günlük!H264/Günlük!H257-1 -> 0.03683235 | F39: =Günlük!I264/Günlük!I257-1 -> 0.048716537 | G39: =Günlük!J264/Günlük!J257-1 -> 0.045976081 | H39: =Günlük!K264/Günlük!K257-1 -> 0.017712272 | I39: =Günlük!L264/Günlük!L257-1 -> 0.061161371 | J39: =Günlük!H264-Günlük!H257 -> 295.84898 | K39: =Günlük!I264-Günlük!I257 -> 449.10657 | L39: =Günlük!J264-Günlük!J257 -> 398.51633 | M39: =Günlük!K264-Günlük!K257 -> 113.02118 | N39: =Günlük!L264-Günlük!L257 -> 588.48125 | O39: =Günlük!H264 -> 8328.1623 | P39: =Günlük!I264 -> 9667.8769 | Q39: =Günlük!J264 -> 9066.422 | R39: =Günlük!K264 -> 6493.9745 | S39: =Günlük!L264 -> 10210.261
A40: 21.09 haftası | B40: =Günlük!A265 -> 46286 | C40: =Günlük!A271 -> 46292 | D40: 7 | E40: =Günlük!H271/Günlük!H264-1 -> -0.080492329 | F40: =Günlük!I271/Günlük!I264-1 -> -0.052705102 | G40: =Günlük!J271/Günlük!J264-1 -> -0.051788265 | H40: =Günlük!K271/Günlük!K264-1 -> -0.054254434 | I40: =Günlük!L271/Günlük!L264-1 -> -0.060065044 | J40: =Günlük!H271-Günlük!H264 -> -670.35318 | K40: =Günlük!I271-Günlük!I264 -> -509.54644 | L40: =Günlük!J271-Günlük!J264 -> -469.53426 | M40: =Günlük!K271-Günlük!K264 -> -352.32691 | N40: =Günlük!L271-Günlük!L264 -> -613.27978 | O40: =Günlük!H271 -> 7657.8091 | P40: =Günlük!I271 -> 9158.3305 | Q40: =Günlük!J271 -> 8596.8877 | R40: =Günlük!K271 -> 6141.6476 | S40: =Günlük!L271 -> 9596.9813
...

Sheet Aylık
A1: Ay | B1: Başlangıç | C1: Bitiş | D1: Gün | E1: T4 (şimdiki) getiri % | F1: T7K 1,15x + koşullu stop getiri % | G1: T7K 1,15x eski stop getiri % | H1: Eski bot T1 getiri % | I1: T6 1x + koşullu stop (bilgi) getiri % | J1: T4 (şimdiki) kâr $ | K1: T7K 1,15x + koşullu stop kâr $ | L1: T7K 1,15x eski stop kâr $ | M1: Eski bot T1 kâr $ | N1: T6 1x + koşullu stop (bilgi) kâr $ | O1: T4 (şimdiki) dönem sonu bakiye $ | P1: T7K 1,15x + koşullu stop dönem sonu bakiye $ | Q1: T7K 1,15x eski stop dönem sonu bakiye $ | R1: Eski bot T1 dönem sonu bakiye $ | S1: T6 1x + koşullu stop (bilgi) dönem sonu bakiye $
A2: Ocak 2026 | B2: =Günlük!A2 -> 46023 | C2: =Günlük!A32 -> 46053 | D2: 31 | E2: =Günlük!H32/Varsayımlar!$B$3-1 -> 0.41141848 | F2: =Günlük!I32/Varsayımlar!$B$3-1 -> 0.42901736 | G2: =Günlük!J32/Varsayımlar!$B$3-1 -> 0.40931262 | H2: =Günlük!K32/Varsayımlar!$B$3-1 -> 0.38327035 | I2: =Günlük!L32/Varsayımlar!$B$3-1 -> 0.4091004 | J2: =Günlük!H32-Varsayımlar!$B$3 -> 822.83697 | K2: =Günlük!I32-Varsayımlar!$B$3 -> 858.03472 | L2: =Günlük!J32-Varsayımlar!$B$3 -> 818.62524 | M2: =Günlük!K32-Varsayımlar!$B$3 -> 766.5407 | N2: =Günlük!L32-Varsayımlar!$B$3 -> 818.20079 | O2: =Günlük!H32 -> 2822.837 | P2: =Günlük!I32 -> 2858.0347 | Q2: =Günlük!J32 -> 2818.6252 | R2: =Günlük!K32 -> 2766.5407 | S2: =Günlük!L32 -> 2818.2008
A3: Şubat 2026 | B3: =Günlük!A33 -> 46054 | C3: =Günlük!A60 -> 46081 | D3: 28 | E3: =Günlük!H60/Günlük!H32-1 -> 0.17058115 | F3: =Günlük!I60/Günlük!I32-1 -> 0.21082841 | G3: =Günlük!J60/Günlük!J32-1 -> 0.20191134 | H3: =Günlük!K60/Günlük!K32-1 -> 0.1612419 | I3: =Günlük!L60/Günlük!L32-1 -> 0.19890991 | J3: =Günlük!H60-Günlük!H32 -> 481.52276 | K3: =Günlük!I60-Günlük!I32 -> 602.55491 | L3: =Günlük!J60-Günlük!J32 -> 569.11239 | M3: =Günlük!K60-Günlük!K32 -> 446.08228 | N3: =Günlük!L60-Günlük!L32 -> 560.56807 | O3: =Günlük!H60 -> 3304.3597 | P3: =Günlük!I60 -> 3460.5896 | Q3: =Günlük!J60 -> 3387.7376 | R3: =Günlük!K60 -> 3212.623 | S3: =Günlük!L60 -> 3378.7689
A4: Mart 2026 | B4: =Günlük!A61 -> 46082 | C4: =Günlük!A91 -> 46112 | D4: 31 | E4: =Günlük!H91/Günlük!H60-1 -> 0.11565339 | F4: =Günlük!I91/Günlük!I60-1 -> 0.090377546 | G4: =Günlük!J91/Günlük!J60-1 -> 0.11777645 | H4: =Günlük!K91/Günlük!K60-1 -> 0.087445395 | I4: =Günlük!L91/Günlük!L60-1 -> 0.10020173 | J4: =Günlük!H91-Günlük!H60 -> 382.1604 | K4: =Günlük!I91-Günlük!I60 -> 312.7596 | L4: =Günlük!J91-Günlük!J60 -> 398.99573 | M4: =Günlük!K91-Günlük!K60 -> 280.92909 | N4: =Günlük!L91-Günlük!L60 -> 338.55849 | O4: =Günlük!H91 -> 3686.5201 | P4: =Günlük!I91 -> 3773.3492 | Q4: =Günlük!J91 -> 3786.7334 | R4: =Günlük!K91 -> 3493.5521 | S4: =Günlük!L91 -> 3717.3274
A5: Nisan 2026 | B5: =Günlük!A92 -> 46113 | C5: =Günlük!A121 -> 46142 | D5: 30 | E5: =Günlük!H121/Günlük!H91-1 -> 0.25753916 | F5: =Günlük!I121/Günlük!I91-1 -> 0.41176836 | G5: =Günlük!J121/Günlük!J91-1 -> 0.33968932 | H5: =Günlük!K121/Günlük!K91-1 -> 0.23520773 | I5: =Günlük!L121/Günlük!L91-1 -> 0.35561358 | J5: =Günlük!H121-Günlük!H91 -> 949.4233 | K5: =Günlük!I121-Günlük!I91 -> 1553.7458 | L5: =Günlük!J121-Günlük!J91 -> 1286.3129 | M5: =Günlük!K121-Günlük!K91 -> 821.71045 | N5: =Günlük!L121-Günlük!L91 -> 1321.9321 | O5: =Günlük!H121 -> 4635.9434 | P5: =Günlük!I121 -> 5327.0951 | Q5: =Günlük!J121 -> 5073.0462 | R5: =Günlük!K121 -> 4315.2625 | S5: =Günlük!L121 -> 5039.2594
A6: Mayıs 2026 | B6: =Günlük!A122 -> 46143 | C6: =Günlük!A152 -> 46173 | D6: 31 | E6: =Günlük!H152/Günlük!H121-1 -> 0.1840709 | F6: =Günlük!I152/Günlük!I121-1 -> 0.16846109 | G6: =Günlük!J152/Günlük!J121-1 -> 0.17157365 | H6: =Günlük!K152/Günlük!K121-1 -> 0.11230982 | I6: =Günlük!L152/Günlük!L121-1 -> 0.17390328 | J6: =Günlük!H152-Günlük!H121 -> 853.34228 | K6: =Günlük!I152-Günlük!I121 -> 897.40826 | L6: =Günlük!J152-Günlük!J121 -> 870.40107 | M6: =Günlük!K152-Günlük!K121 -> 484.64635 | N6: =Günlük!L152-Günlük!L121 -> 876.34373 | O6: =Günlük!H152 -> 5489.2857 | P6: =Günlük!I152 -> 6224.5033 | Q6: =Günlük!J152 -> 5943.4473 | R6: =Günlük!K152 -> 4799.9089 | S6: =Günlük!L152 -> 5915.6032
A7: Haziran 2026 | B7: =Günlük!A153 -> 46174 | C7: =Günlük!A182 -> 46203 | D7: 30 | E7: =Günlük!H182/Günlük!H152-1 -> 0.18942394 | F7: =Günlük!I182/Günlük!I152-1 -> 0.23658292 | G7: =Günlük!J182/Günlük!J152-1 -> 0.21269326 | H7: =Günlük!K182/Günlük!K152-1 -> 0.17487464 | I7: =Günlük!L182/Günlük!L152-1 -> 0.31156978 | J7: =Günlük!H182-Günlük!H152 -> 1039.8021 | K7: =Günlük!I182-Günlük!I152 -> 1472.6112 | L7: =Günlük!J182-Günlük!J152 -> 1264.1312 | M7: =Günlük!K182-Günlük!K152 -> 839.38233 | N7: =Günlük!L182-Günlük!L152 -> 1843.1232 | O7: =Günlük!H182 -> 6529.0879 | P7: =Günlük!I182 -> 7697.1145 | Q7: =Günlük!J182 -> 7207.5785 | R7: =Günlük!K182 -> 5639.2912 | S7: =Günlük!L182 -> 7758.7263
A8: Temmuz 2026 | B8: =Günlük!A183 -> 46204 | C8: =Günlük!A213 -> 46234 | D8: 31 | E8: =Günlük!H213/Günlük!H182-1 -> 0.02819021 | F8: =Günlük!I213/Günlük!I182-1 -> 0.0090666083 | G8: =Günlük!J213/Günlük!J182-1 -> 0.021348364 | H8: =Günlük!K213/Günlük!K182-1 -> -0.026734206 | I8: =Günlük!L213/Günlük!L182-1 -> 0.01620786 | J8: =Günlük!H213-Günlük!H182 -> 184.05636 | K8: =Günlük!I213-Günlük!I182 -> 69.786722 | L8: =Günlük!J213-Günlük!J182 -> 153.87001 | M8: =Günlük!K213-Günlük!K182 -> -150.76197 | N8: =Günlük!L213-Günlük!L182 -> 125.75235 | O8: =Günlük!H213 -> 6713.1442 | P8: =Günlük!I213 -> 7766.9012 | Q8: =Günlük!J213 -> 7361.4485 | R8: =Günlük!K213 -> 5488.5292 | S8: =Günlük!L213 -> 7884.4787
A9: Ağustos 2026 | B9: =Günlük!A214 -> 46235 | C9: =Günlük!A244 -> 46265 | D9: 31 | E9: =Günlük!H244/Günlük!H213-1 -> 0.094074089 | F9: =Günlük!I244/Günlük!I213-1 -> 0.10273869 | G9: =Günlük!J244/Günlük!J213-1 -> 0.092424998 | H9: =Günlük!K244/Günlük!K213-1 -> 0.08990911 | I9: =Günlük!L244/Günlük!L213-1 -> 0.11570986 | J9: =Günlük!H244-Günlük!H213 -> 631.53293 | K9: =Günlük!I244-Günlük!I213 -> 797.96128 | L9: =Günlük!J244-Günlük!J213 -> 680.38187 | M9: =Günlük!K244-Günlük!K213 -> 493.46878 | N9: =Günlük!L244-Günlük!L213 -> 912.3119 | O9: =Günlük!H244 -> 7344.6771 | P9: =Günlük!I244 -> 8564.8625 | Q9: =Günlük!J244 -> 8041.8304 | R9: =Günlük!K244 -> 5981.998 | S9: =Günlük!L244 -> 8796.7906
A10: Eylül 2026 | B10: =Günlük!A245 -> 46266 | C10: =Günlük!A274 -> 46295 | D10: 30 | E10: =Günlük!H274/Günlük!H244-1 -> 0.045480841 | F10: =Günlük!I274/Günlük!I244-1 -> 0.083578935 | G10: =Günlük!J274/Günlük!J244-1 -> 0.083305531 | H10: =Günlük!K274/Günlük!K244-1 -> 0.04855718 | I10: =Günlük!L274/Günlük!L244-1 -> 0.11666121 | J10: =Günlük!H274-Günlük!H244 -> 334.04209 | K10: =Günlük!I274-Günlük!I244 -> 715.84209 | L10: =Günlük!J274-Günlük!J244 -> 669.92896 | M10: =Günlük!K274-Günlük!K244 -> 290.46896 | N10: =Günlük!L274-Günlük!L244 -> 1026.2443 | O10: =Günlük!H274 -> 7678.7192 | P10: =Günlük!I274 -> 9280.7046 | Q10: =Günlük!J274 -> 8711.7594 | R10: =Günlük!K274 -> 6272.4669 | S10: =Günlük!L274 -> 9823.0349
