Workbook

Sheet Yıllık
A1: Yıl | B1: Dönem sonu | C1: Gün | D1: Eski bot % | E1: Eski bot $ | F1: T60 % | G1: T60 $ | H1: T60 x kaldıraç % | I1: T60 x kaldıraç $ | J1: Kayıp gün (eski) | K1: Kayıp gün (T60) | L1: En kötü gün (T60)
A2: 2022 (20 Tem-Ara) | B2: 44926 | C2: =COUNTIFS(Günlük!$A$2:$A$1535,">="&DATE(2022,7,20),Günlük!$A$2:$A$1535,"<="&B2) -> 165 | D2: =E2/Varsayımlar!$B$2-1 -> 0.083769636 | E2: =INDEX(Günlük!$C$2:$C$1535,MATCH(B2,Günlük!$A$2:$A$1535,1)) -> 2167.5393 | F2: =G2/Varsayımlar!$B$2-1 -> 0.086564352 | G2: =INDEX(Günlük!$E$2:$E$1535,MATCH(B2,Günlük!$A$2:$A$1535,1)) -> 2173.1287 | H2: =I2/Varsayımlar!$B$2-1 -> 0.10044384 | I2: =INDEX(Günlük!$G$2:$G$1535,MATCH(B2,Günlük!$A$2:$A$1535,1)) -> 2200.8877 | J2: =COUNTIFS(Günlük!$A$2:$A$1535,">="&DATE(2022,7,20),Günlük!$A$2:$A$1535,"<="&B2,Günlük!$B$2:$B$1535,"<0") -> 78 | K2: =COUNTIFS(Günlük!$A$2:$A$1535,">="&DATE(2022,7,20),Günlük!$A$2:$A$1535,"<="&B2,Günlük!$D$2:$D$1535,"<0") -> 83 | L2: =_xlfn.MINIFS(Günlük!$D$2:$D$1535,Günlük!$A$2:$A$1535,">="&DATE(2022,7,20),Günlük!$A$2:$A$1535,"<="&B2) -> -0.08628006
A3: 2023 | B3: 45291 | C3: =COUNTIFS(Günlük!$A$2:$A$1535,">="&DATE(2023,1,1),Günlük!$A$2:$A$1535,"<="&B3) -> 365 | D3: =E3/E2-1 -> 2.0051789 | E3: =INDEX(Günlük!$C$2:$C$1535,MATCH(B3,Günlük!$A$2:$A$1535,1)) -> 6513.8432 | F3: =G3/G2-1 -> 3.0821698 | G3: =INDEX(Günlük!$E$2:$E$1535,MATCH(B3,Günlük!$A$2:$A$1535,1)) -> 8871.0804 | H3: =I3/I2-1 -> 4.6973986 | I3: =INDEX(Günlük!$G$2:$G$1535,MATCH(B3,Günlük!$A$2:$A$1535,1)) -> 12539.334 | J3: =COUNTIFS(Günlük!$A$2:$A$1535,">="&DATE(2023,1,1),Günlük!$A$2:$A$1535,"<="&B3,Günlük!$B$2:$B$1535,"<0") -> 164 | K3: =COUNTIFS(Günlük!$A$2:$A$1535,">="&DATE(2023,1,1),Günlük!$A$2:$A$1535,"<="&B3,Günlük!$D$2:$D$1535,"<0") -> 157 | L3: =_xlfn.MINIFS(Günlük!$D$2:$D$1535,Günlük!$A$2:$A$1535,">="&DATE(2023,1,1),Günlük!$A$2:$A$1535,"<="&B3) -> -0.04343677
A4: 2024 | B4: 45657 | C4: =COUNTIFS(Günlük!$A$2:$A$1535,">="&DATE(2024,1,1),Günlük!$A$2:$A$1535,"<="&B4) -> 366 | D4: =E4/E3-1 -> 1.0047844 | E4: =INDEX(Günlük!$C$2:$C$1535,MATCH(B4,Günlük!$A$2:$A$1535,1)) -> 13058.851 | F4: =G4/G3-1 -> 1.2521192 | G4: =INDEX(Günlük!$E$2:$E$1535,MATCH(B4,Günlük!$A$2:$A$1535,1)) -> 19978.73 | H4: =I4/I3-1 -> 1.7131794 | I4: =INDEX(Günlük!$G$2:$G$1535,MATCH(B4,Günlük!$A$2:$A$1535,1)) -> 34021.464 | J4: =COUNTIFS(Günlük!$A$2:$A$1535,">="&DATE(2024,1,1),Günlük!$A$2:$A$1535,"<="&B4,Günlük!$B$2:$B$1535,"<0") -> 169 | K4: =COUNTIFS(Günlük!$A$2:$A$1535,">="&DATE(2024,1,1),Günlük!$A$2:$A$1535,"<="&B4,Günlük!$D$2:$D$1535,"<0") -> 171 | L4: =_xlfn.MINIFS(Günlük!$D$2:$D$1535,Günlük!$A$2:$A$1535,">="&DATE(2024,1,1),Günlük!$A$2:$A$1535,"<="&B4) -> -0.06768454
A5: 2025 | B5: 46022 | C5: =COUNTIFS(Günlük!$A$2:$A$1535,">="&DATE(2025,1,1),Günlük!$A$2:$A$1535,"<="&B5) -> 365 | D5: =E5/E4-1 -> 1.0302451 | E5: =INDEX(Günlük!$C$2:$C$1535,MATCH(B5,Günlük!$A$2:$A$1535,1)) -> 26512.668 | F5: =G5/G4-1 -> 2.5256409 | G5: =INDEX(Günlük!$E$2:$E$1535,MATCH(B5,Günlük!$A$2:$A$1535,1)) -> 70437.829 | H5: =I5/I4-1 -> 3.7211262 | I5: =INDEX(Günlük!$G$2:$G$1535,MATCH(B5,Günlük!$A$2:$A$1535,1)) -> 160619.63 | J5: =COUNTIFS(Günlük!$A$2:$A$1535,">="&DATE(2025,1,1),Günlük!$A$2:$A$1535,"<="&B5,Günlük!$B$2:$B$1535,"<0") -> 173 | K5: =COUNTIFS(Günlük!$A$2:$A$1535,">="&DATE(2025,1,1),Günlük!$A$2:$A$1535,"<="&B5,Günlük!$D$2:$D$1535,"<0") -> 162 | L5: =_xlfn.MINIFS(Günlük!$D$2:$D$1535,Günlük!$A$2:$A$1535,">="&DATE(2025,1,1),Günlük!$A$2:$A$1535,"<="&B5) -> -0.06580859
A6: 2026 (Oca-Eyl) | B6: 46295 | C6: =COUNTIFS(Günlük!$A$2:$A$1535,">="&DATE(2026,1,1),Günlük!$A$2:$A$1535,"<="&B6) -> 273 | D6: =E6/E5-1 -> 1.424823 | E6: =INDEX(Günlük!$C$2:$C$1535,MATCH(B6,Günlük!$A$2:$A$1535,1)) -> 64288.527 | F6: =G6/G5-1 -> 2.8602774 | G6: =INDEX(Günlük!$E$2:$E$1535,MATCH(B6,Günlük!$A$2:$A$1535,1)) -> 271909.56 | H6: =I6/I5-1 -> 4.2881377 | I6: =INDEX(Günlük!$G$2:$G$1535,MATCH(B6,Günlük!$A$2:$A$1535,1)) -> 849378.71 | J6: =COUNTIFS(Günlük!$A$2:$A$1535,">="&DATE(2026,1,1),Günlük!$A$2:$A$1535,"<="&B6,Günlük!$B$2:$B$1535,"<0") -> 114 | K6: =COUNTIFS(Günlük!$A$2:$A$1535,">="&DATE(2026,1,1),Günlük!$A$2:$A$1535,"<="&B6,Günlük!$D$2:$D$1535,"<0") -> 109 | L6: =_xlfn.MINIFS(Günlük!$D$2:$D$1535,Günlük!$A$2:$A$1535,">="&DATE(2026,1,1),Günlük!$A$2:$A$1535,"<="&B6) -> -0.08608767
A8: Tüm dönem | D8: =E6/Varsayımlar!$B$2-1 -> 31.144264 | E8: =E6 -> 64288.527 | F8: =G6/Varsayımlar!$B$2-1 -> 134.95478 | G8: =G6 -> 271909.56 | H8: =I6/Varsayımlar!$B$2-1 -> 423.68935 | I8: =I6 -> 849378.71
A9: Yıllık ortalama (bileşik) | D9: =(E6/Varsayımlar!$B$2)^(365.25/COUNT(Günlük!$A$2:$A$1535))-1 -> 1.2847877 | F9: =(G6/Varsayımlar!$B$2)^(365.25/COUNT(Günlük!$A$2:$A$1535))-1 -> 2.2208287 | H9: =(I6/Varsayımlar!$B$2)^(365.25/COUNT(Günlük!$A$2:$A$1535))-1 -> 3.2242701
A11: Not: 2022 ve 2026 tam yıl değil. Bileşik bakiyeler büyük hesaplarda gerçekçi değildir (likidite).

Sheet Aylık
A1: Ay | B1: Dönem sonu | C1: Gün | D1: Eski bot % | E1: Eski bot $ | F1: T60 % | G1: T60 $ | H1: T60 x kaldıraç % | I1: T60 x kaldıraç $ | J1: Kayıp gün (eski) | K1: Kayıp gün (T60) | L1: En kötü gün (T60)
A2: 2022-07 | B2: 44773 | C2: =COUNTIFS(Günlük!$A$2:$A$1535,">="&DATE(2022,7,20),Günlük!$A$2:$A$1535,"<="&B2) -> 12 | D2: =E2/Varsayımlar!$B$2-1 -> -0.003563847 | E2: =INDEX(Günlük!$C$2:$C$1535,MATCH(B2,Günlük!$A$2:$A$1535,1)) -> 1992.8723 | F2: =G2/Varsayımlar!$B$2-1 -> -0.04539006 | G2: =INDEX(Günlük!$E$2:$E$1535,MATCH(B2,Günlük!$A$2:$A$1535,1)) -> 1909.2199 | H2: =I2/Varsayımlar!$B$2-1 -> -0.057219755 | I2: =INDEX(Günlük!$G$2:$G$1535,MATCH(B2,Günlük!$A$2:$A$1535,1)) -> 1885.5605 | J2: =COUNTIFS(Günlük!$A$2:$A$1535,">="&DATE(2022,7,20),Günlük!$A$2:$A$1535,"<="&B2,Günlük!$B$2:$B$1535,"<0") -> 6 | K2: =COUNTIFS(Günlük!$A$2:$A$1535,">="&DATE(2022,7,20),Günlük!$A$2:$A$1535,"<="&B2,Günlük!$D$2:$D$1535,"<0") -> 7 | L2: =_xlfn.MINIFS(Günlük!$D$2:$D$1535,Günlük!$A$2:$A$1535,">="&DATE(2022,7,20),Günlük!$A$2:$A$1535,"<="&B2) -> -0.05470949
A3: 2022-08 | B3: 44804 | C3: =COUNTIFS(Günlük!$A$2:$A$1535,">="&DATE(2022,8,1),Günlük!$A$2:$A$1535,"<="&B3) -> 31 | D3: =E3/E2-1 -> -0.0010119224 | E3: =INDEX(Günlük!$C$2:$C$1535,MATCH(B3,Günlük!$A$2:$A$1535,1)) -> 1990.8557 | F3: =G3/G2-1 -> -0.020316393 | G3: =INDEX(Günlük!$E$2:$E$1535,MATCH(B3,Günlük!$A$2:$A$1535,1)) -> 1870.4314 | H3: =I3/I2-1 -> -0.025872244 | I3: =INDEX(Günlük!$G$2:$G$1535,MATCH(B3,Günlük!$A$2:$A$1535,1)) -> 1836.7768 | J3: =COUNTIFS(Günlük!$A$2:$A$1535,">="&DATE(2022,8,1),Günlük!$A$2:$A$1535,"<="&B3,Günlük!$B$2:$B$1535,"<0") -> 14 | K3: =COUNTIFS(Günlük!$A$2:$A$1535,">="&DATE(2022,8,1),Günlük!$A$2:$A$1535,"<="&B3,Günlük!$D$2:$D$1535,"<0") -> 18 | L3: =_xlfn.MINIFS(Günlük!$D$2:$D$1535,Günlük!$A$2:$A$1535,">="&DATE(2022,8,1),Günlük!$A$2:$A$1535,"<="&B3) -> -0.02279533
A4: 2022-09 | B4: 44834 | C4: =COUNTIFS(Günlük!$A$2:$A$1535,">="&DATE(2022,9,1),Günlük!$A$2:$A$1535,"<="&B4) -> 30 | D4: =E4/E3-1 -> 0.016672501 | E4: =INDEX(Günlük!$C$2:$C$1535,MATCH(B4,Günlük!$A$2:$A$1535,1)) -> 2024.0482 | F4: =G4/G3-1 -> 0.030769847 | G4: =INDEX(Günlük!$E$2:$E$1535,MATCH(B4,Günlük!$A$2:$A$1535,1)) -> 1927.9843 | H4: =I4/I3-1 -> 0.038065126 | I4: =INDEX(Günlük!$G$2:$G$1535,MATCH(B4,Günlük!$A$2:$A$1535,1)) -> 1906.6939 | J4: =COUNTIFS(Günlük!$A$2:$A$1535,">="&DATE(2022,9,1),Günlük!$A$2:$A$1535,"<="&B4,Günlük!$B$2:$B$1535,"<0") -> 12 | K4: =COUNTIFS(Günlük!$A$2:$A$1535,">="&DATE(2022,9,1),Günlük!$A$2:$A$1535,"<="&B4,Günlük!$D$2:$D$1535,"<0") -> 14 | L4: =_xlfn.MINIFS(Günlük!$D$2:$D$1535,Günlük!$A$2:$A$1535,">="&DATE(2022,9,1),Günlük!$A$2:$A$1535,"<="&B4) -> -0.02919857
A5: 2022-10 | B5: 44865 | C5: =COUNTIFS(Günlük!$A$2:$A$1535,">="&DATE(2022,10,1),Günlük!$A$2:$A$1535,"<="&B5) -> 31 | D5: =E5/E4-1 -> 0.018542278 | E5: =INDEX(Günlük!$C$2:$C$1535,MATCH(B5,Günlük!$A$2:$A$1535,1)) -> 2061.5787 | F5: =G5/G4-1 -> 0.053883564 | G5: =INDEX(Günlük!$E$2:$E$1535,MATCH(B5,Günlük!$A$2:$A$1535,1)) -> 2031.871 | H5: =I5/I4-1 -> 0.06700767 | I5: =INDEX(Günlük!$G$2:$G$1535,MATCH(B5,Günlük!$A$2:$A$1535,1)) -> 2034.4571 | J5: =COUNTIFS(Günlük!$A$2:$A$1535,">="&DATE(2022,10,1),Günlük!$A$2:$A$1535,"<="&B5,Günlük!$B$2:$B$1535,"<0") -> 16 | K5: =COUNTIFS(Günlük!$A$2:$A$1535,">="&DATE(2022,10,1),Günlük!$A$2:$A$1535,"<="&B5,Günlük!$D$2:$D$1535,"<0") -> 14 | L5: =_xlfn.MINIFS(Günlük!$D$2:$D$1535,Günlük!$A$2:$A$1535,">="&DATE(2022,10,1),Günlük!$A$2:$A$1535,"<="&B5) -> -0.01959102
A6: 2022-11 | B6: 44895 | C6: =COUNTIFS(Günlük!$A$2:$A$1535,">="&DATE(2022,11,1),Günlük!$A$2:$A$1535,"<="&B6) -> 30 | D6: =E6/E5-1 -> 0.0077383386 | E6: =INDEX(Günlük!$C$2:$C$1535,MATCH(B6,Günlük!$A$2:$A$1535,1)) -> 2077.5319 | F6: =G6/G5-1 -> 0.03015807 | G6: =INDEX(Günlük!$E$2:$E$1535,MATCH(B6,Günlük!$A$2:$A$1535,1)) -> 2093.1483 | H6: =I6/I5-1 -> 0.032562957 | I6: =INDEX(Günlük!$G$2:$G$1535,MATCH(B6,Günlük!$A$2:$A$1535,1)) -> 2100.705 | J6: =COUNTIFS(Günlük!$A$2:$A$1535,">="&DATE(2022,11,1),Günlük!$A$2:$A$1535,"<="&B6,Günlük!$B$2:$B$1535,"<0") -> 17 | K6: =COUNTIFS(Günlük!$A$2:$A$1535,">="&DATE(2022,11,1),Günlük!$A$2:$A$1535,"<="&B6,Günlük!$D$2:$D$1535,"<0") -> 17 | L6: =_xlfn.MINIFS(Günlük!$D$2:$D$1535,Günlük!$A$2:$A$1535,">="&DATE(2022,11,1),Günlük!$A$2:$A$1535,"<="&B6) -> -0.08628006
A7: 2022-12 | B7: 44926 | C7: =COUNTIFS(Günlük!$A$2:$A$1535,">="&DATE(2022,12,1),Günlük!$A$2:$A$1535,"<="&B7) -> 31 | D7: =E7/E6-1 -> 0.043324196 | E7: =INDEX(Günlük!$C$2:$C$1535,MATCH(B7,Günlük!$A$2:$A$1535,1)) -> 2167.5393 | F7: =G7/G6-1 -> 0.038210587 | G7: =INDEX(Günlük!$E$2:$E$1535,MATCH(B7,Günlük!$A$2:$A$1535,1)) -> 2173.1287 | H7: =I7/I6-1 -> 0.047690024 | I7: =INDEX(Günlük!$G$2:$G$1535,MATCH(B7,Günlük!$A$2:$A$1535,1)) -> 2200.8877 | J7: =COUNTIFS(Günlük!$A$2:$A$1535,">="&DATE(2022,12,1),Günlük!$A$2:$A$1535,"<="&B7,Günlük!$B$2:$B$1535,"<0") -> 13 | K7: =COUNTIFS(Günlük!$A$2:$A$1535,">="&DATE(2022,12,1),Günlük!$A$2:$A$1535,"<="&B7,Günlük!$D$2:$D$1535,"<0") -> 13 | L7: =_xlfn.MINIFS(Günlük!$D$2:$D$1535,Günlük!$A$2:$A$1535,">="&DATE(2022,12,1),Günlük!$A$2:$A$1535,"<="&B7) -> -0.01456133
A8: 2023-01 | B8: 44957 | C8: =COUNTIFS(Günlük!$A$2:$A$1535,">="&DATE(2023,1,1),Günlük!$A$2:$A$1535,"<="&B8) -> 31 | D8: =E8/E7-1 -> 0.11890661 | E8: =INDEX(Günlük!$C$2:$C$1535,MATCH(B8,Günlük!$A$2:$A$1535,1)) -> 2425.274 | F8: =G8/G7-1 -> 0.18160891 | G8: =INDEX(Günlük!$E$2:$E$1535,MATCH(B8,Günlük!$A$2:$A$1535,1)) -> 2567.7882 | H8: =I8/I7-1 -> 0.22979244 | I8: =INDEX(Günlük!$G$2:$G$1535,MATCH(B8,Günlük!$A$2:$A$1535,1)) -> 2706.635 | J8: =COUNTIFS(Günlük!$A$2:$A$1535,">="&DATE(2023,1,1),Günlük!$A$2:$A$1535,"<="&B8,Günlük!$B$2:$B$1535,"<0") -> 14 | K8: =COUNTIFS(Günlük!$A$2:$A$1535,">="&DATE(2023,1,1),Günlük!$A$2:$A$1535,"<="&B8,Günlük!$D$2:$D$1535,"<0") -> 12 | L8: =_xlfn.MINIFS(Günlük!$D$2:$D$1535,Günlük!$A$2:$A$1535,">="&DATE(2023,1,1),Günlük!$A$2:$A$1535,"<="&B8) -> -0.01614038
A9: 2023-02 | B9: 44985 | C9: =COUNTIFS(Günlük!$A$2:$A$1535,">="&DATE(2023,2,1),Günlük!$A$2:$A$1535,"<="&B9) -> 28 | D9: =E9/E8-1 -> -0.059563607 | E9: =INDEX(Günlük!$C$2:$C$1535,MATCH(B9,Günlük!$A$2:$A$1535,1)) -> 2280.8159 | F9: =G9/G8-1 -> -0.09328144 | G9: =INDEX(Günlük!$E$2:$E$1535,MATCH(B9,Günlük!$A$2:$A$1535,1)) -> 2328.2613 | H9: =I9/I8-1 -> -0.11578039 | I9: =INDEX(Günlük!$G$2:$G$1535,MATCH(B9,Günlük!$A$2:$A$1535,1)) -> 2393.2598 | J9: =COUNTIFS(Günlük!$A$2:$A$1535,">="&DATE(2023,2,1),Günlük!$A$2:$A$1535,"<="&B9,Günlük!$B$2:$B$1535,"<0") -> 17 | K9: =COUNTIFS(Günlük!$A$2:$A$1535,">="&DATE(2023,2,1),Günlük!$A$2:$A$1535,"<="&B9,Günlük!$D$2:$D$1535,"<0") -> 16 | L9: =_xlfn.MINIFS(Günlük!$D$2:$D$1535,Günlük!$A$2:$A$1535,">="&DATE(2023,2,1),Günlük!$A$2:$A$1535,"<="&B9) -> -0.03773948
A10: 2023-03 | B10: 45016 | C10: =COUNTIFS(Günlük!$A$2:$A$1535,">="&DATE(2023,3,1),Günlük!$A$2:$A$1535,"<="&B10) -> 31 | D10: =E10/E9-1 -> 0.029912626 | E10: =INDEX(Günlük!$C$2:$C$1535,MATCH(B10,Günlük!$A$2:$A$1535,1)) -> 2349.0411 | F10: =G10/G9-1 -> 0.079225813 | G10: =INDEX(Günlük!$E$2:$E$1535,MATCH(B10,Günlük!$A$2:$A$1535,1)) -> 2512.7196 | H10: =I10/I9-1 -> 0.098911832 | I10: =INDEX(Günlük!$G$2:$G$1535,MATCH(B10,Günlük!$A$2:$A$1535,1)) -> 2629.9815 | J10: =COUNTIFS(Günlük!$A$2:$A$1535,">="&DATE(2023,3,1),Günlük!$A$2:$A$1535,"<="&B10,Günlük!$B$2:$B$1535,"<0") -> 14 | K10: =COUNTIFS(Günlük!$A$2:$A$1535,">="&DATE(2023,3,1),Günlük!$A$2:$A$1535,"<="&B10,Günlük!$D$2:$D$1535,"<0") -> 11 | L10: =_xlfn.MINIFS(Günlük!$D$2:$D$1535,Günlük!$A$2:$A$1535,">="&DATE(2023,3,1),Günlük!$A$2:$A$1535,"<="&B10) -> -0.0337768
A11: 2023-04 | B11: 45046 | C11: =COUNTIFS(Günlük!$A$2:$A$1535,">="&DATE(2023,4,1),Günlük!$A$2:$A$1535,"<="&B11) -> 30 | D11: =E11/E10-1 -> 0.025471027 | E11: =INDEX(Günlük!$C$2:$C$1535,MATCH(B11,Günlük!$A$2:$A$1535,1)) -> 2408.8736 | F11: =G11/G10-1 -> 0.081043827 | G11: =INDEX(Günlük!$E$2:$E$1535,MATCH(B11,Günlük!$A$2:$A$1535,1)) -> 2716.3601 | H11: =I11/I10-1 -> 0.10139019 | I11: =INDEX(Günlük!$G$2:$G$1535,MATCH(B11,Günlük!$A$2:$A$1535,1)) -> 2896.6358 | J11: =COUNTIFS(Günlük!$A$2:$A$1535,">="&DATE(2023,4,1),Günlük!$A$2:$A$1535,"<="&B11,Günlük!$B$2:$B$1535,"<0") -> 17 | K11: =COUNTIFS(Günlük!$A$2:$A$1535,">="&DATE(2023,4,1),Günlük!$A$2:$A$1535,"<="&B11,Günlük!$D$2:$D$1535,"<0") -> 15 | L11: =_xlfn.MINIFS(Günlük!$D$2:$D$1535,Günlük!$A$2:$A$1535,">="&DATE(2023,4,1),Günlük!$A$2:$A$1535,"<="&B11) -> -0.02024781
A12: 2023-05 | B12: 45077 | C12: =COUNTIFS(Günlük!$A$2:$A$1535,">="&DATE(2023,5,1),Günlük!$A$2:$A$1535,"<="&B12) -> 31 | D12: =E12/E11-1 -> 0.20072239 | E12: =INDEX(Günlük!$C$2:$C$1535,MATCH(B12,Günlük!$A$2:$A$1535,1)) -> 2892.3885 | F12: =G12/G11-1 -> 0.2036341 | G12: =INDEX(Günlük!$E$2:$E$1535,MATCH(B12,Günlük!$A$2:$A$1535,1)) -> 3269.5036 | H12: =I12/I11-1 -> 0.25905447 | I12: =INDEX(Günlük!$G$2:$G$1535,MATCH(B12,Günlük!$A$2:$A$1535,1)) -> 3647.0223 | J12: =COUNTIFS(Günlük!$A$2:$A$1535,">="&DATE(2023,5,1),Günlük!$A$2:$A$1535,"<="&B12,Günlük!$B$2:$B$1535,"<0") -> 8 | K12: =COUNTIFS(Günlük!$A$2:$A$1535,">="&DATE(2023,5,1),Günlük!$A$2:$A$1535,"<="&B12,Günlük!$D$2:$D$1535,"<0") -> 10 | L12: =_xlfn.MINIFS(Günlük!$D$2:$D$1535,Günlük!$A$2:$A$1535,">="&DATE(2023,5,1),Günlük!$A$2:$A$1535,"<="&B12) -> -0.02033543
A13: 2023-06 | B13: 45107 | C13: =COUNTIFS(Günlük!$A$2:$A$1535,">="&DATE(2023,6,1),Günlük!$A$2:$A$1535,"<="&B13) -> 30 | D13: =E13/E12-1 -> 0.0065072803 | E13: =INDEX(Günlük!$C$2:$C$1535,MATCH(B13,Günlük!$A$2:$A$1535,1)) -> 2911.2101 | F13: =G13/G12-1 -> -0.0062842551 | G13: =INDEX(Günlük!$E$2:$E$1535,MATCH(B13,Günlük!$A$2:$A$1535,1)) -> 3248.9572 | H13: =I13/I12-1 -> -0.0082775865 | I13: =INDEX(Günlük!$G$2:$G$1535,MATCH(B13,Günlük!$A$2:$A$1535,1)) -> 3616.8337 | J13: =COUNTIFS(Günlük!$A$2:$A$1535,">="&DATE(2023,6,1),Günlük!$A$2:$A$1535,"<="&B13,Günlük!$B$2:$B$1535,"<0") -> 15 | K13: =COUNTIFS(Günlük!$A$2:$A$1535,">="&DATE(2023,6,1),Günlük!$A$2:$A$1535,"<="&B13,Günlük!$D$2:$D$1535,"<0") -> 17 | L13: =_xlfn.MINIFS(Günlük!$D$2:$D$1535,Günlük!$A$2:$A$1535,">="&DATE(2023,6,1),Günlük!$A$2:$A$1535,"<="&B13) -> -0.01761483
A14: 2023-07 | B14: 45138 | C14: =COUNTIFS(Günlük!$A$2:$A$1535,">="&DATE(2023,7,1),Günlük!$A$2:$A$1535,"<="&B14) -> 31 | D14: =E14/E13-1 -> 0.011401726 | E14: =INDEX(Günlük!$C$2:$C$1535,MATCH(B14,Günlük!$A$2:$A$1535,1)) -> 2944.4029 | F14: =G14/G13-1 -> 0.040488638 | G14: =INDEX(Günlük!$E$2:$E$1535,MATCH(B14,Günlük!$A$2:$A$1535,1)) -> 3380.5031 | H14: =I14/I13-1 -> 0.049616042 | I14: =INDEX(Günlük!$G$2:$G$1535,MATCH(B14,Günlük!$A$2:$A$1535,1)) -> 3796.2867 | J14: =COUNTIFS(Günlük!$A$2:$A$1535,">="&DATE(2023,7,1),Günlük!$A$2:$A$1535,"<="&B14,Günlük!$B$2:$B$1535,"<0") -> 16 | K14: =COUNTIFS(Günlük!$A$2:$A$1535,">="&DATE(2023,7,1),Günlük!$A$2:$A$1535,"<="&B14,Günlük!$D$2:$D$1535,"<0") -> 15 | L14: =_xlfn.MINIFS(Günlük!$D$2:$D$1535,Günlük!$A$2:$A$1535,">="&DATE(2023,7,1),Günlük!$A$2:$A$1535,"<="&B14) -> -0.04343677
A15: 2023-08 | B15: 45169 | C15: =COUNTIFS(Günlük!$A$2:$A$1535,">="&DATE(2023,8,1),Günlük!$A$2:$A$1535,"<="&B15) -> 31 | D15: =E15/E14-1 -> 0.31493877 | E15: =INDEX(Günlük!$C$2:$C$1535,MATCH(B15,Günlük!$A$2:$A$1535,1)) -> 3871.7095 | F15: =G15/G14-1 -> 0.34419309 | G15: =INDEX(Günlük!$E$2:$E$1535,MATCH(B15,Günlük!$A$2:$A$1535,1)) -> 4544.0489 | H15: =I15/I14-1 -> 0.44418557 | I15: =INDEX(Günlük!$G$2:$G$1535,MATCH(B15,Günlük!$A$2:$A$1535,1)) -> 5482.5425 | J15: =COUNTIFS(Günlük!$A$2:$A$1535,">="&DATE(2023,8,1),Günlük!$A$2:$A$1535,"<="&B15,Günlük!$B$2:$B$1535,"<0") -> 10 | K15: =COUNTIFS(Günlük!$A$2:$A$1535,">="&DATE(2023,8,1),Günlük!$A$2:$A$1535,"<="&B15,Günlük!$D$2:$D$1535,"<0") -> 12 | L15: =_xlfn.MINIFS(Günlük!$D$2:$D$1535,Günlük!$A$2:$A$1535,">="&DATE(2023,8,1),Günlük!$A$2:$A$1535,"<="&B15) -> -0.0268687
A16: 2023-09 | B16: 45199 | C16: =COUNTIFS(Günlük!$A$2:$A$1535,">="&DATE(2023,9,1),Günlük!$A$2:$A$1535,"<="&B16) -> 30 | D16: =E16/E15-1 -> 0.4263381 | E16: =INDEX(Günlük!$C$2:$C$1535,MATCH(B16,Günlük!$A$2:$A$1535,1)) -> 5522.3668 | F16: =G16/G15-1 -> 0.52471267 | G16: =INDEX(Günlük!$E$2:$E$1535,MATCH(B16,Günlük!$A$2:$A$1535,1)) -> 6928.3689 | H16: =I16/I15-1 -> 0.68677944 | I16: =INDEX(Günlük!$G$2:$G$1535,MATCH(B16,Günlük!$A$2:$A$1535,1)) -> 9247.8399 | J16: =COUNTIFS(Günlük!$A$2:$A$1535,">="&DATE(2023,9,1),Günlük!$A$2:$A$1535,"<="&B16,Günlük!$B$2:$B$1535,"<0") -> 11 | K16: =COUNTIFS(Günlük!$A$2:$A$1535,">="&DATE(2023,9,1),Günlük!$A$2:$A$1535,"<="&B16,Günlük!$D$2:$D$1535,"<0") -> 10 | L16: =_xlfn.MINIFS(Günlük!$D$2:$D$1535,Günlük!$A$2:$A$1535,">="&DATE(2023,9,1),Günlük!$A$2:$A$1535,"<="&B16) -> -0.03110893
A17: 2023-10 | B17: 45230 | C17: =COUNTIFS(Günlük!$A$2:$A$1535,">="&DATE(2023,10,1),Günlük!$A$2:$A$1535,"<="&B17) -> 31 | D17: =E17/E16-1 -> 0.054249424 | E17: =INDEX(Günlük!$C$2:$C$1535,MATCH(B17,Günlük!$A$2:$A$1535,1)) -> 5821.952 | F17: =G17/G16-1 -> 0.069532522 | G17: =INDEX(Günlük!$E$2:$E$1535,MATCH(B17,Günlük!$A$2:$A$1535,1)) -> 7410.1158 | H17: =I17/I16-1 -> 0.08578773 | I17: =INDEX(Günlük!$G$2:$G$1535,MATCH(B17,Günlük!$A$2:$A$1535,1)) -> 10041.191 | J17: =COUNTIFS(Günlük!$A$2:$A$1535,">="&DATE(2023,10,1),Günlük!$A$2:$A$1535,"<="&B17,Günlük!$B$2:$B$1535,"<0") -> 14 | K17: =COUNTIFS(Günlük!$A$2:$A$1535,">="&DATE(2023,10,1),Günlük!$A$2:$A$1535,"<="&B17,Günlük!$D$2:$D$1535,"<0") -> 14 | L17: =_xlfn.MINIFS(Günlük!$D$2:$D$1535,Günlük!$A$2:$A$1535,">="&DATE(2023,10,1),Günlük!$A$2:$A$1535,"<="&B17) -> -0.03735486
A18: 2023-11 | B18: 45260 | C18: =COUNTIFS(Günlük!$A$2:$A$1535,">="&DATE(2023,11,1),Günlük!$A$2:$A$1535,"<="&B18) -> 30 | D18: =E18/E17-1 -> 0.042729533 | E18: =INDEX(Günlük!$C$2:$C$1535,MATCH(B18,Günlük!$A$2:$A$1535,1)) -> 6070.7213 | F18: =G18/G17-1 -> 0.066613122 | G18: =INDEX(Günlük!$E$2:$E$1535,MATCH(B18,Günlük!$A$2:$A$1535,1)) -> 7903.7268 | H18: =I18/I17-1 -> 0.083369813 | I18: =INDEX(Günlük!$G$2:$G$1535,MATCH(B18,Günlük!$A$2:$A$1535,1)) -> 10878.323 | J18: =COUNTIFS(Günlük!$A$2:$A$1535,">="&DATE(2023,11,1),Günlük!$A$2:$A$1535,"<="&B18,Günlük!$B$2:$B$1535,"<0") -> 16 | K18: =COUNTIFS(Günlük!$A$2:$A$1535,">="&DATE(2023,11,1),Günlük!$A$2:$A$1535,"<="&B18,Günlük!$D$2:$D$1535,"<0") -> 14 | L18: =_xlfn.MINIFS(Günlük!$D$2:$D$1535,Günlük!$A$2:$A$1535,">="&DATE(2023,11,1),Günlük!$A$2:$A$1535,"<="&B18) -> -0.01195122
A19: 2023-12 | B19: 45291 | C19: =COUNTIFS(Günlük!$A$2:$A$1535,">="&DATE(2023,12,1),Günlük!$A$2:$A$1535,"<="&B19) -> 31 | D19: =E19/E18-1 -> 0.072993281 | E19: =INDEX(Günlük!$C$2:$C$1535,MATCH(B19,Günlük!$A$2:$A$1535,1)) -> 6513.8432 | F19: =G19/G18-1 -> 0.12239209 | G19: =INDEX(Günlük!$E$2:$E$1535,MATCH(B19,Günlük!$A$2:$A$1535,1)) -> 8871.0804 | H19: =I19/I18-1 -> 0.15269 | I19: =INDEX(Günlük!$G$2:$G$1535,MATCH(B19,Günlük!$A$2:$A$1535,1)) -> 12539.334 | J19: =COUNTIFS(Günlük!$A$2:$A$1535,">="&DATE(2023,12,1),Günlük!$A$2:$A$1535,"<="&B19,Günlük!$B$2:$B$1535,"<0") -> 12 | K19: =COUNTIFS(Günlük!$A$2:$A$1535,">="&DATE(2023,12,1),Günlük!$A$2:$A$1535,"<="&B19,Günlük!$D$2:$D$1535,"<0") -> 11 | L19: =_xlfn.MINIFS(Günlük!$D$2:$D$1535,Günlük!$A$2:$A$1535,">="&DATE(2023,12,1),Günlük!$A$2:$A$1535,"<="&B19) -> -0.04214302
A20: 2024-01 | B20: 45322 | C20: =COUNTIFS(Günlük!$A$2:$A$1535,">="&DATE(2024,1,1),Günlük!$A$2:$A$1535,"<="&B20) -> 31 | D20: =E20/E19-1 -> -0.010115989 | E20: =INDEX(Günlük!$C$2:$C$1535,MATCH(B20,Günlük!$A$2:$A$1535,1)) -> 6447.9492 | F20: =G20/G19-1 -> -0.0082725623 | G20: =INDEX(Günlük!$E$2:$E$1535,MATCH(B20,Günlük!$A$2:$A$1535,1)) -> 8797.6938 | H20: =I20/I19-1 -> -0.011448562 | I20: =INDEX(Günlük!$G$2:$G$1535,MATCH(B20,Günlük!$A$2:$A$1535,1)) -> 12395.777 | J20: =COUNTIFS(Günlük!$A$2:$A$1535,">="&DATE(2024,1,1),Günlük!$A$2:$A$1535,"<="&B20,Günlük!$B$2:$B$1535,"<0") -> 19 | K20: =COUNTIFS(Günlük!$A$2:$A$1535,">="&DATE(2024,1,1),Günlük!$A$2:$A$1535,"<="&B20,Günlük!$D$2:$D$1535,"<0") -> 19 | L20: =_xlfn.MINIFS(Günlük!$D$2:$D$1535,Günlük!$A$2:$A$1535,">="&DATE(2024,1,1),Günlük!$A$2:$A$1535,"<="&B20) -> -0.02326514
A21: 2024-02 | B21: 45351 | C21: =COUNTIFS(Günlük!$A$2:$A$1535,">="&DATE(2024,2,1),Günlük!$A$2:$A$1535,"<="&B21) -> 29 | D21: =E21/E20-1 -> -0.095486866 | E21: =INDEX(Günlük!$C$2:$C$1535,MATCH(B21,Günlük!$A$2:$A$1535,1)) -> 5832.2548 | F21: =G21/G20-1 -> -0.039757281 | G21: =INDEX(Günlük!$E$2:$E$1535,MATCH(B21,Günlük!$A$2:$A$1535,1)) -> 8447.9214 | H21: =I21/I20-1 -> -0.0502551 | I21: =INDEX(Günlük!$G$2:$G$1535,MATCH(B21,Günlük!$A$2:$A$1535,1)) -> 11772.826 | J21: =COUNTIFS(Günlük!$A$2:$A$1535,">="&DATE(2024,2,1),Günlük!$A$2:$A$1535,"<="&B21,Günlük!$B$2:$B$1535,"<0") -> 14 | K21: =COUNTIFS(Günlük!$A$2:$A$1535,">="&DATE(2024,2,1),Günlük!$A$2:$A$1535,"<="&B21,Günlük!$D$2:$D$1535,"<0") -> 15 | L21: =_xlfn.MINIFS(Günlük!$D$2:$D$1535,Günlük!$A$2:$A$1535,">="&DATE(2024,2,1),Günlük!$A$2:$A$1535,"<="&B21) -> -0.04239721
A22: 2024-03 | B22: 45382 | C22: =COUNTIFS(Günlük!$A$2:$A$1535,">="&DATE(2024,3,1),Günlük!$A$2:$A$1535,"<="&B22) -> 31 | D22: =E22/E21-1 -> 0.15682584 | E22: =INDEX(Günlük!$C$2:$C$1535,MATCH(B22,Günlük!$A$2:$A$1535,1)) -> 6746.903 | F22: =G22/G21-1 -> 0.23097007 | G22: =INDEX(Günlük!$E$2:$E$1535,MATCH(B22,Günlük!$A$2:$A$1535,1)) -> 10399.138 | H22: =I22/I21-1 -> 0.29271244 | I22: =INDEX(Günlük!$G$2:$G$1535,MATCH(B22,Günlük!$A$2:$A$1535,1)) -> 15218.879 | J22: =COUNTIFS(Günlük!$A$2:$A$1535,">="&DATE(2024,3,1),Günlük!$A$2:$A$1535,"<="&B22,Günlük!$B$2:$B$1535,"<0") -> 13 | K22: =COUNTIFS(Günlük!$A$2:$A$1535,">="&DATE(2024,3,1),Günlük!$A$2:$A$1535,"<="&B22,Günlük!$D$2:$D$1535,"<0") -> 13 | L22: =_xlfn.MINIFS(Günlük!$D$2:$D$1535,Günlük!$A$2:$A$1535,">="&DATE(2024,3,1),Günlük!$A$2:$A$1535,"<="&B22) -> -0.04502792
A23: 2024-04 | B23: 45412 | C23: =COUNTIFS(Günlük!$A$2:$A$1535,">="&DATE(2024,4,1),Günlük!$A$2:$A$1535,"<="&B23) -> 30 | D23: =E23/E22-1 -> 0.082701463 | E23: =INDEX(Günlük!$C$2:$C$1535,MATCH(B23,Günlük!$A$2:$A$1535,1)) -> 7304.8818 | F23: =G23/G22-1 -> 0.093212622 | G23: =INDEX(Günlük!$E$2:$E$1535,MATCH(B23,Günlük!$A$2:$A$1535,1)) -> 11368.469 | H23: =I23/I22-1 -> 0.11606722 | I23: =INDEX(Günlük!$G$2:$G$1535,MATCH(B23,Günlük!$A$2:$A$1535,1)) -> 16985.292 | J23: =COUNTIFS(Günlük!$A$2:$A$1535,">="&DATE(2024,4,1),Günlük!$A$2:$A$1535,"<="&B23,Günlük!$B$2:$B$1535,"<0") -> 11 | K23: =COUNTIFS(Günlük!$A$2:$A$1535,">="&DATE(2024,4,1),Günlük!$A$2:$A$1535,"<="&B23,Günlük!$D$2:$D$1535,"<0") -> 12 | L23: =_xlfn.MINIFS(Günlük!$D$2:$D$1535,Günlük!$A$2:$A$1535,">="&DATE(2024,4,1),Günlük!$A$2:$A$1535,"<="&B23) -> -0.04993554
A24: 2024-05 | B24: 45443 | C24: =COUNTIFS(Günlük!$A$2:$A$1535,">="&DATE(2024,5,1),Günlük!$A$2:$A$1535,"<="&B24) -> 31 | D24: =E24/E23-1 -> 0.020921829 | E24: =INDEX(Günlük!$C$2:$C$1535,MATCH(B24,Günlük!$A$2:$A$1535,1)) -> 7457.7133 | F24: =G24/G23-1 -> -0.02913821 | G24: =INDEX(Günlük!$E$2:$E$1535,MATCH(B24,Günlük!$A$2:$A$1535,1)) -> 11037.213 | H24: =I24/I23-1 -> -0.037149143 | I24: =INDEX(Günlük!$G$2:$G$1535,MATCH(B24,Günlük!$A$2:$A$1535,1)) -> 16354.303 | J24: =COUNTIFS(Günlük!$A$2:$A$1535,">="&DATE(2024,5,1),Günlük!$A$2:$A$1535,"<="&B24,Günlük!$B$2:$B$1535,"<0") -> 14 | K24: =COUNTIFS(Günlük!$A$2:$A$1535,">="&DATE(2024,5,1),Günlük!$A$2:$A$1535,"<="&B24,Günlük!$D$2:$D$1535,"<0") -> 19 | L24: =_xlfn.MINIFS(Günlük!$D$2:$D$1535,Günlük!$A$2:$A$1535,">="&DATE(2024,5,1),Günlük!$A$2:$A$1535,"<="&B24) -> -0.02608972
A25: 2024-06 | B25: 45473 | C25: =COUNTIFS(Günlük!$A$2:$A$1535,">="&DATE(2024,6,1),Günlük!$A$2:$A$1535,"<="&B25) -> 30 | D25: =E25/E24-1 -> 0.0092421221 | E25: =INDEX(Günlük!$C$2:$C$1535,MATCH(B25,Günlük!$A$2:$A$1535,1)) -> 7526.6384 | F25: =G25/G24-1 -> -0.039427776 | G25: =INDEX(Günlük!$E$2:$E$1535,MATCH(B25,Günlük!$A$2:$A$1535,1)) -> 10602.04 | H25: =I25/I24-1 -> -0.05033294 | I25: =INDEX(Günlük!$G$2:$G$1535,MATCH(B25,Günlük!$A$2:$A$1535,1)) -> 15531.142 | J25: =COUNTIFS(Günlük!$A$2:$A$1535,">="&DATE(2024,6,1),Günlük!$A$2:$A$1535,"<="&B25,Günlük!$B$2:$B$1535,"<0") -> 15 | K25: =COUNTIFS(Günlük!$A$2:$A$1535,">="&DATE(2024,6,1),Günlük!$A$2:$A$1535,"<="&B25,Günlük!$D$2:$D$1535,"<0") -> 16 | L25: =_xlfn.MINIFS(Günlük!$D$2:$D$1535,Günlük!$A$2:$A$1535,">="&DATE(2024,6,1),Günlük!$A$2:$A$1535,"<="&B25) -> -0.03611868
A26: 2024-07 | B26: 45504 | C26: =COUNTIFS(Günlük!$A$2:$A$1535,">="&DATE(2024,7,1),Günlük!$A$2:$A$1535,"<="&B26) -> 31 | D26: =E26/E25-1 -> 0.077758131 | E26: =INDEX(Günlük!$C$2:$C$1535,MATCH(B26,Günlük!$A$2:$A$1535,1)) -> 8111.8957 | F26: =G26/G25-1 -> 0.089528488 | G26: =INDEX(Günlük!$E$2:$E$1535,MATCH(B26,Günlük!$A$2:$A$1535,1)) -> 11551.224 | H26: =I26/I25-1 -> 0.11179894 | I26: =INDEX(Günlük!$G$2:$G$1535,MATCH(B26,Günlük!$A$2:$A$1535,1)) -> 17267.508 | J26: =COUNTIFS(Günlük!$A$2:$A$1535,">="&DATE(2024,7,1),Günlük!$A$2:$A$1535,"<="&B26,Günlük!$B$2:$B$1535,"<0") -> 16 | K26: =COUNTIFS(Günlük!$A$2:$A$1535,">="&DATE(2024,7,1),Günlük!$A$2:$A$1535,"<="&B26,Günlük!$D$2:$D$1535,"<0") -> 13 | L26: =_xlfn.MINIFS(Günlük!$D$2:$D$1535,Günlük!$A$2:$A$1535,">="&DATE(2024,7,1),Günlük!$A$2:$A$1535,"<="&B26) -> -0.02934143
A27: 2024-08 | B27: 45535 | C27: =COUNTIFS(Günlük!$A$2:$A$1535,">="&DATE(2024,8,1),Günlük!$A$2:$A$1535,"<="&B27) -> 31 | D27: =E27/E26-1 -> -0.005993459 | E27: =INDEX(Günlük!$C$2:$C$1535,MATCH(B27,Günlük!$A$2:$A$1535,1)) -> 8063.2774 | F27: =G27/G26-1 -> -0.018574263 | G27: =INDEX(Günlük!$E$2:$E$1535,MATCH(B27,Günlük!$A$2:$A$1535,1)) -> 11336.669 | H27: =I27/I26-1 -> -0.023450354 | I27: =INDEX(Günlük!$G$2:$G$1535,MATCH(B27,Günlük!$A$2:$A$1535,1)) -> 16862.579 | J27: =COUNTIFS(Günlük!$A$2:$A$1535,">="&DATE(2024,8,1),Günlük!$A$2:$A$1535,"<="&B27,Günlük!$B$2:$B$1535,"<0") -> 18 | K27: =COUNTIFS(Günlük!$A$2:$A$1535,">="&DATE(2024,8,1),Günlük!$A$2:$A$1535,"<="&B27,Günlük!$D$2:$D$1535,"<0") -> 18 | L27: =_xlfn.MINIFS(Günlük!$D$2:$D$1535,Günlük!$A$2:$A$1535,">="&DATE(2024,8,1),Günlük!$A$2:$A$1535,"<="&B27) -> -0.01524829
A28: 2024-09 | B28: 45565 | C28: =COUNTIFS(Günlük!$A$2:$A$1535,">="&DATE(2024,9,1),Günlük!$A$2:$A$1535,"<="&B28) -> 30 | D28: =E28/E27-1 -> 0.072359909 | E28: =INDEX(Günlük!$C$2:$C$1535,MATCH(B28,Günlük!$A$2:$A$1535,1)) -> 8646.7354 | F28: =G28/G27-1 -> 0.089270888 | G28: =INDEX(Günlük!$E$2:$E$1535,MATCH(B28,Günlük!$A$2:$A$1535,1)) -> 12348.703 | H28: =I28/I27-1 -> 0.11145645 | I28: =INDEX(Günlük!$G$2:$G$1535,MATCH(B28,Günlük!$A$2:$A$1535,1)) -> 18742.022 | J28: =COUNTIFS(Günlük!$A$2:$A$1535,">="&DATE(2024,9,1),Günlük!$A$2:$A$1535,"<="&B28,Günlük!$B$2:$B$1535,"<0") -> 15 | K28: =COUNTIFS(Günlük!$A$2:$A$1535,">="&DATE(2024,9,1),Günlük!$A$2:$A$1535,"<="&B28,Günlük!$D$2:$D$1535,"<0") -> 13 | L28: =_xlfn.MINIFS(Günlük!$D$2:$D$1535,Günlük!$A$2:$A$1535,">="&DATE(2024,9,1),Günlük!$A$2:$A$1535,"<="&B28) -> -0.03339318
A29: 2024-10 | B29: 45596 | C29: =COUNTIFS(Günlük!$A$2:$A$1535,">="&DATE(2024,10,1),Günlük!$A$2:$A$1535,"<="&B29) -> 31 | D29: =E29/E28-1 -> 0.047286698 | E29: =INDEX(Günlük!$C$2:$C$1535,MATCH(B29,Günlük!$A$2:$A$1535,1)) -> 9055.611 | F29: =G29/G28-1 -> -0.018967902 | G29: =INDEX(Günlük!$E$2:$E$1535,MATCH(B29,Günlük!$A$2:$A$1535,1)) -> 12114.474 | H29: =I29/I28-1 -> -0.024760659 | I29: =INDEX(Günlük!$G$2:$G$1535,MATCH(B29,Günlük!$A$2:$A$1535,1)) -> 18277.957 | J29: =COUNTIFS(Günlük!$A$2:$A$1535,">="&DATE(2024,10,1),Günlük!$A$2:$A$1535,"<="&B29,Günlük!$B$2:$B$1535,"<0") -> 14 | K29: =COUNTIFS(Günlük!$A$2:$A$1535,">="&DATE(2024,10,1),Günlük!$A$2:$A$1535,"<="&B29,Günlük!$D$2:$D$1535,"<0") -> 14 | L29: =_xlfn.MINIFS(Günlük!$D$2:$D$1535,Günlük!$A$2:$A$1535,">="&DATE(2024,10,1),Günlük!$A$2:$A$1535,"<="&B29) -> -0.06768454
A30: 2024-11 | B30: 45626 | C30: =COUNTIFS(Günlük!$A$2:$A$1535,">="&DATE(2024,11,1),Günlük!$A$2:$A$1535,"<="&B30) -> 30 | D30: =E30/E29-1 -> 0.12814409 | E30: =INDEX(Günlük!$C$2:$C$1535,MATCH(B30,Günlük!$A$2:$A$1535,1)) -> 10216.034 | F30: =G30/G29-1 -> 0.22322008 | G30: =INDEX(Günlük!$E$2:$E$1535,MATCH(B30,Günlük!$A$2:$A$1535,1)) -> 14818.668 | H30: =I30/I29-1 -> 0.28460192 | I30: =INDEX(Günlük!$G$2:$G$1535,MATCH(B30,Günlük!$A$2:$A$1535,1)) -> 23479.898 | J30: =COUNTIFS(Günlük!$A$2:$A$1535,">="&DATE(2024,11,1),Günlük!$A$2:$A$1535,"<="&B30,Günlük!$B$2:$B$1535,"<0") -> 10 | K30: =COUNTIFS(Günlük!$A$2:$A$1535,">="&DATE(2024,11,1),Günlük!$A$2:$A$1535,"<="&B30,Günlük!$D$2:$D$1535,"<0") -> 9 | L30: =_xlfn.MINIFS(Günlük!$D$2:$D$1535,Günlük!$A$2:$A$1535,">="&DATE(2024,11,1),Günlük!$A$2:$A$1535,"<="&B30) -> -0.03328895
A31: 2024-12 | B31: 45657 | C31: =COUNTIFS(Günlük!$A$2:$A$1535,">="&DATE(2024,12,1),Günlük!$A$2:$A$1535,"<="&B31) -> 31 | D31: =E31/E30-1 -> 0.27827011 | E31: =INDEX(Günlük!$C$2:$C$1535,MATCH(B31,Günlük!$A$2:$A$1535,1)) -> 13058.851 | F31: =G31/G30-1 -> 0.3482136 | G31: =INDEX(Günlük!$E$2:$E$1535,MATCH(B31,Günlük!$A$2:$A$1535,1)) -> 19978.73 | H31: =I31/I30-1 -> 0.44896131 | I31: =INDEX(Günlük!$G$2:$G$1535,MATCH(B31,Günlük!$A$2:$A$1535,1)) -> 34021.464 | J31: =COUNTIFS(Günlük!$A$2:$A$1535,">="&DATE(2024,12,1),Günlük!$A$2:$A$1535,"<="&B31,Günlük!$B$2:$B$1535,"<0") -> 10 | K31: =COUNTIFS(Günlük!$A$2:$A$1535,">="&DATE(2024,12,1),Günlük!$A$2:$A$1535,"<="&B31,Günlük!$D$2:$D$1535,"<0") -> 10 | L31: =_xlfn.MINIFS(Günlük!$D$2:$D$1535,Günlük!$A$2:$A$1535,">="&DATE(2024,12,1),Günlük!$A$2:$A$1535,"<="&B31) -> -0.03281926
A32: 2025-01 | B32: 45688 | C32: =COUNTIFS(Günlük!$A$2:$A$1535,">="&DATE(2025,1,1),Günlük!$A$2:$A$1535,"<="&B32) -> 31 | D32: =E32/E31-1 -> 0.040832505 | E32: =INDEX(Günlük!$C$2:$C$1535,MATCH(B32,Günlük!$A$2:$A$1535,1)) -> 13592.077 | F32: =G32/G31-1 -> 0.11699409 | G32: =INDEX(Günlük!$E$2:$E$1535,MATCH(B32,Günlük!$A$2:$A$1535,1)) -> 22316.124 | H32: =I32/I31-1 -> 0.14613334 | I32: =INDEX(Günlük!$G$2:$G$1535,MATCH(B32,Günlük!$A$2:$A$1535,1)) -> 38993.135 | J32: =COUNTIFS(Günlük!$A$2:$A$1535,">="&DATE(2025,1,1),Günlük!$A$2:$A$1535,"<="&B32,Günlük!$B$2:$B$1535,"<0") -> 14 | K32: =COUNTIFS(Günlük!$A$2:$A$1535,">="&DATE(2025,1,1),Günlük!$A$2:$A$1535,"<="&B32,Günlük!$D$2:$D$1535,"<0") -> 13 | L32: =_xlfn.MINIFS(Günlük!$D$2:$D$1535,Günlük!$A$2:$A$1535,">="&DATE(2025,1,1),Günlük!$A$2:$A$1535,"<="&B32) -> -0.03556087
A33: 2025-02 | B33: 45716 | C33: =COUNTIFS(Günlük!$A$2:$A$1535,">="&DATE(2025,2,1),Günlük!$A$2:$A$1535,"<="&B33) -> 28 | D33: =E33/E32-1 -> 0.10110719 | E33: =INDEX(Günlük!$C$2:$C$1535,MATCH(B33,Günlük!$A$2:$A$1535,1)) -> 14966.333 | F33: =G33/G32-1 -> 0.064240291 | G33: =INDEX(Günlük!$E$2:$E$1535,MATCH(B33,Günlük!$A$2:$A$1535,1)) -> 23749.718 | H33: =I33/I32-1 -> 0.079382587 | I33: =INDEX(Günlük!$G$2:$G$1535,MATCH(B33,Günlük!$A$2:$A$1535,1)) -> 42088.511 | J33: =COUNTIFS(Günlük!$A$2:$A$1535,">="&DATE(2025,2,1),Günlük!$A$2:$A$1535,"<="&B33,Günlük!$B$2:$B$1535,"<0") -> 14 | K33: =COUNTIFS(Günlük!$A$2:$A$1535,">="&DATE(2025,2,1),Günlük!$A$2:$A$1535,"<="&B33,Günlük!$D$2:$D$1535,"<0") -> 11 | L33: =_xlfn.MINIFS(Günlük!$D$2:$D$1535,Günlük!$A$2:$A$1535,">="&DATE(2025,2,1),Günlük!$A$2:$A$1535,"<="&B33) -> -0.03427738
A34: 2025-03 | B34: 45747 | C34: =COUNTIFS(Günlük!$A$2:$A$1535,">="&DATE(2025,3,1),Günlük!$A$2:$A$1535,"<="&B34) -> 31 | D34: =E34/E33-1 -> 0.13621572 | E34: =INDEX(Günlük!$C$2:$C$1535,MATCH(B34,Günlük!$A$2:$A$1535,1)) -> 17004.983 | F34: =G34/G33-1 -> 0.19226703 | G34: =INDEX(Günlük!$E$2:$E$1535,MATCH(B34,Günlük!$A$2:$A$1535,1)) -> 28316.006 | H34: =I34/I33-1 -> 0.24158511 | I34: =INDEX(Günlük!$G$2:$G$1535,MATCH(B34,Günlük!$A$2:$A$1535,1)) -> 52256.468 | J34: =COUNTIFS(Günlük!$A$2:$A$1535,">="&DATE(2025,3,1),Günlük!$A$2:$A$1535,"<="&B34,Günlük!$B$2:$B$1535,"<0") -> 10 | K34: =COUNTIFS(Günlük!$A$2:$A$1535,">="&DATE(2025,3,1),Günlük!$A$2:$A$1535,"<="&B34,Günlük!$D$2:$D$1535,"<0") -> 11 | L34: =_xlfn.MINIFS(Günlük!$D$2:$D$1535,Günlük!$A$2:$A$1535,">="&DATE(2025,3,1),Günlük!$A$2:$A$1535,"<="&B34) -> -0.05314096
A35: 2025-04 | B35: 45777 | C35: =COUNTIFS(Günlük!$A$2:$A$1535,">="&DATE(2025,4,1),Günlük!$A$2:$A$1535,"<="&B35) -> 30 | D35: =E35/E34-1 -> 0.054368952 | E35: =INDEX(Günlük!$C$2:$C$1535,MATCH(B35,Günlük!$A$2:$A$1535,1)) -> 17929.526 | F35: =G35/G34-1 -> 0.10341403 | G35: =INDEX(Günlük!$E$2:$E$1535,MATCH(B35,Günlük!$A$2:$A$1535,1)) -> 31244.278 | H35: =I35/I34-1 -> 0.12669554 | I35: =INDEX(Günlük!$G$2:$G$1535,MATCH(B35,Günlük!$A$2:$A$1535,1)) -> 58877.129 | J35: =COUNTIFS(Günlük!$A$2:$A$1535,">="&DATE(2025,4,1),Günlük!$A$2:$A$1535,"<="&B35,Günlük!$B$2:$B$1535,"<0") -> 17 | K35: =COUNTIFS(Günlük!$A$2:$A$1535,">="&DATE(2025,4,1),Günlük!$A$2:$A$1535,"<="&B35,Günlük!$D$2:$D$1535,"<0") -> 14 | L35: =_xlfn.MINIFS(Günlük!$D$2:$D$1535,Günlük!$A$2:$A$1535,">="&DATE(2025,4,1),Günlük!$A$2:$A$1535,"<="&B35) -> -0.06580859
A36: 2025-05 | B36: 45808 | C36: =COUNTIFS(Günlük!$A$2:$A$1535,">="&DATE(2025,5,1),Günlük!$A$2:$A$1535,"<="&B36) -> 31 | D36: =E36/E35-1 -> -0.013635112 | E36: =INDEX(Günlük!$C$2:$C$1535,MATCH(B36,Günlük!$A$2:$A$1535,1)) -> 17685.055 | F36: =G36/G35-1 -> -0.010454814 | G36: =INDEX(Günlük!$E$2:$E$1535,MATCH(B36,Günlük!$A$2:$A$1535,1)) -> 30917.625 | H36: =I36/I35-1 -> -0.013885532 | I36: =INDEX(Günlük!$G$2:$G$1535,MATCH(B36,Günlük!$A$2:$A$1535,1)) -> 58059.589 | J36: =COUNTIFS(Günlük!$A$2:$A$1535,">="&DATE(2025,5,1),Günlük!$A$2:$A$1535,"<="&B36,Günlük!$B$2:$B$1535,"<0") -> 18 | K36: =COUNTIFS(Günlük!$A$2:$A$1535,">="&DATE(2025,5,1),Günlük!$A$2:$A$1535,"<="&B36,Günlük!$D$2:$D$1535,"<0") -> 16 | L36: =_xlfn.MINIFS(Günlük!$D$2:$D$1535,Günlük!$A$2:$A$1535,">="&DATE(2025,5,1),Günlük!$A$2:$A$1535,"<="&B36) -> -0.03864233
A37: 2025-06 | B37: 45838 | C37: =COUNTIFS(Günlük!$A$2:$A$1535,">="&DATE(2025,6,1),Günlük!$A$2:$A$1535,"<="&B37) -> 30 | D37: =E37/E36-1 -> 0.052344025 | E37: =INDEX(Günlük!$C$2:$C$1535,MATCH(B37,Günlük!$A$2:$A$1535,1)) -> 18610.762 | F37: =G37/G36-1 -> 0.13871771 | G37: =INDEX(Günlük!$E$2:$E$1535,MATCH(B37,Günlük!$A$2:$A$1535,1)) -> 35206.447 | H37: =I37/I36-1 -> 0.17467646 | I37: =INDEX(Günlük!$G$2:$G$1535,MATCH(B37,Günlük!$A$2:$A$1535,1)) -> 68201.233 | J37: =COUNTIFS(Günlük!$A$2:$A$1535,">="&DATE(2025,6,1),Günlük!$A$2:$A$1535,"<="&B37,Günlük!$B$2:$B$1535,"<0") -> 13 | K37: =COUNTIFS(Günlük!$A$2:$A$1535,">="&DATE(2025,6,1),Günlük!$A$2:$A$1535,"<="&B37,Günlük!$D$2:$D$1535,"<0") -> 12 | L37: =_xlfn.MINIFS(Günlük!$D$2:$D$1535,Günlük!$A$2:$A$1535,">="&DATE(2025,6,1),Günlük!$A$2:$A$1535,"<="&B37) -> -0.03253493
A38: 2025-07 | B38: 45869 | C38: =COUNTIFS(Günlük!$A$2:$A$1535,">="&DATE(2025,7,1),Günlük!$A$2:$A$1535,"<="&B38) -> 31 | D38: =E38/E37-1 -> 0.010983797 | E38: =INDEX(Günlük!$C$2:$C$1535,MATCH(B38,Günlük!$A$2:$A$1535,1)) -> 18815.179 | F38: =G38/G37-1 -> -0.0066075514 | G38: =INDEX(Günlük!$E$2:$E$1535,MATCH(B38,Günlük!$A$2:$A$1535,1)) -> 34973.818 | H38: =I38/I37-1 -> -0.0097003949 | I38: =INDEX(Günlük!$G$2:$G$1535,MATCH(B38,Günlük!$A$2:$A$1535,1)) -> 67539.654 | J38: =COUNTIFS(Günlük!$A$2:$A$1535,">="&DATE(2025,7,1),Günlük!$A$2:$A$1535,"<="&B38,Günlük!$B$2:$B$1535,"<0") -> 14 | K38: =COUNTIFS(Günlük!$A$2:$A$1535,">="&DATE(2025,7,1),Günlük!$A$2:$A$1535,"<="&B38,Günlük!$D$2:$D$1535,"<0") -> 17 | L38: =_xlfn.MINIFS(Günlük!$D$2:$D$1535,Günlük!$A$2:$A$1535,">="&DATE(2025,7,1),Günlük!$A$2:$A$1535,"<="&B38) -> -0.03064381
A39: 2025-08 | B39: 45900 | C39: =COUNTIFS(Günlük!$A$2:$A$1535,">="&DATE(2025,8,1),Günlük!$A$2:$A$1535,"<="&B39) -> 31 | D39: =E39/E38-1 -> -0.013329412 | E39: =INDEX(Günlük!$C$2:$C$1535,MATCH(B39,Günlük!$A$2:$A$1535,1)) -> 18564.384 | F39: =G39/G38-1 -> 0.0539144 | G39: =INDEX(Günlük!$E$2:$E$1535,MATCH(B39,Günlük!$A$2:$A$1535,1)) -> 36859.411 | H39: =I39/I38-1 -> 0.067044924 | I39: =INDEX(Günlük!$G$2:$G$1535,MATCH(B39,Günlük!$A$2:$A$1535,1)) -> 72067.845 | J39: =COUNTIFS(Günlük!$A$2:$A$1535,">="&DATE(2025,8,1),Günlük!$A$2:$A$1535,"<="&B39,Günlük!$B$2:$B$1535,"<0") -> 19 | K39: =COUNTIFS(Günlük!$A$2:$A$1535,">="&DATE(2025,8,1),Günlük!$A$2:$A$1535,"<="&B39,Günlük!$D$2:$D$1535,"<0") -> 16 | L39: =_xlfn.MINIFS(Günlük!$D$2:$D$1535,Günlük!$A$2:$A$1535,">="&DATE(2025,8,1),Günlük!$A$2:$A$1535,"<="&B39) -> -0.02256977
A40: 2025-09 | B40: 45930 | C40: =COUNTIFS(Günlük!$A$2:$A$1535,">="&DATE(2025,9,1),Günlük!$A$2:$A$1535,"<="&B40) -> 30 | D40: =E40/E39-1 -> -0.020421296 | E40: =INDEX(Günlük!$C$2:$C$1535,MATCH(B40,Günlük!$A$2:$A$1535,1)) -> 18185.275 | F40: =G40/G39-1 -> 0.036537723 | G40: =INDEX(Günlük!$E$2:$E$1535,MATCH(B40,Günlük!$A$2:$A$1535,1)) -> 38206.17 | H40: =I40/I39-1 -> 0.044884026 | I40: =INDEX(Günlük!$G$2:$G$1535,MATCH(B40,Günlük!$A$2:$A$1535,1)) -> 75302.54 | J40: =COUNTIFS(Günlük!$A$2:$A$1535,">="&DATE(2025,9,1),Günlük!$A$2:$A$1535,"<="&B40,Günlük!$B$2:$B$1535,"<0") -> 15 | K40: =COUNTIFS(Günlük!$A$2:$A$1535,">="&DATE(2025,9,1),Günlük!$A$2:$A$1535,"<="&B40,Günlük!$D$2:$D$1535,"<0") -> 14 | L40: =_xlfn.MINIFS(Günlük!$D$2:$D$1535,Günlük!$A$2:$A$1535,">="&DATE(2025,9,1),Günlük!$A$2:$A$1535,"<="&B40) -> -0.03739119
...

Sheet Günlük
A1: Tarih | B1: Eski bot % | C1: Eski bot $ | D1: T60 % | E1: T60 $ | F1: T60 x kaldıraç % | G1: T60 x kaldıraç $
A2: 44762 | B2: 0.00429279 | C2: =Varsayımlar!$B$2*(1+B2) -> 2008.5856 | D2: 0.00639425 | E2: =Varsayımlar!$B$2*(1+D2) -> 2012.7885 | F2: =D2*Varsayımlar!$B$3 -> 0.0079928125 | G2: =Varsayımlar!$B$2*(1+F2) -> 2015.9856
A3: 44763 | B3: 0.01368384 | C3: =C2*(1+B3) -> 2036.0707 | D3: 0.01114971 | E3: =E2*(1+D3) -> 2035.2305 | F3: =D3*Varsayımlar!$B$3 -> 0.013937138 | G3: =G2*(1+F3) -> 2044.0827
A4: 44764 | B4: -0.00345545 | C4: =C3*(1+B4) -> 2029.0352 | D4: -0.00191173 | E4: =E3*(1+D4) -> 2031.3397 | F4: =D4*Varsayımlar!$B$3 -> -0.0023896625 | G4: =G3*(1+F4) -> 2039.198
A5: 44765 | B5: -0.0057255 | C5: =C4*(1+B5) -> 2017.418 | D5: -0.00674468 | E5: =E4*(1+D5) -> 2017.639 | F5: =D5*Varsayımlar!$B$3 -> -0.00843085 | G5: =G4*(1+F5) -> 2022.0059
A6: 44766 | B6: 0.00505254 | C6: =C5*(1+B6) -> 2027.611 | D6: 0.00594902 | E6: =E5*(1+D6) -> 2029.6419 | F6: =D6*Varsayımlar!$B$3 -> 0.007436275 | G6: =G5*(1+F6) -> 2037.042
A7: 44767 | B7: -0.00860304 | C7: =C6*(1+B7) -> 2010.1674 | D7: -0.00541731 | E7: =E6*(1+D7) -> 2018.6467 | F7: =D7*Varsayımlar!$B$3 -> -0.0067716375 | G7: =G6*(1+F7) -> 2023.2479
A8: 44768 | B8: 0.00069356 | C8: =C7*(1+B8) -> 2011.5616 | D8: -0.00123293 | E8: =E7*(1+D8) -> 2016.1579 | F8: =D8*Varsayımlar!$B$3 -> -0.0015411625 | G8: =G7*(1+F8) -> 2020.1298
A9: 44769 | B9: 0.0221779 | C9: =C8*(1+B9) -> 2056.1738 | D9: 0.02555709 | E9: =E8*(1+D9) -> 2067.685 | F9: =D9*Varsayımlar!$B$3 -> 0.031946362 | G9: =G8*(1+F9) -> 2084.6656
A10: 44770 | B10: 0.01566171 | C10: =C9*(1+B10) -> 2088.377 | D10: 0.01778834 | E10: =E9*(1+D10) -> 2104.4657 | F10: =D10*Varsayımlar!$B$3 -> 0.022235425 | G10: =G9*(1+F10) -> 2131.019
A11: 44771 | B11: -0.00318778 | C11: =C10*(1+B11) -> 2081.7197 | D11: -0.01180606 | E11: =E10*(1+D11) -> 2079.6202 | F11: =D11*Varsayımlar!$B$3 -> -0.014757575 | G11: =G10*(1+F11) -> 2099.5703
A12: 44772 | B12: -0.02299613 | C12: =C11*(1+B12) -> 2033.8482 | D12: -0.05470949 | E12: =E11*(1+D12) -> 1965.8453 | F12: =D12*Varsayımlar!$B$3 -> -0.068386863 | G12: =G11*(1+F12) -> 1955.9873
A13: 44773 | B13: -0.02014699 | C13: =C12*(1+B13) -> 1992.8723 | D13: -0.02880461 | E13: =E12*(1+D13) -> 1909.2199 | F13: =D13*Varsayımlar!$B$3 -> -0.036005763 | G13: =G12*(1+F13) -> 1885.5605
A14: 44774 | B14: -0.00341622 | C14: =C13*(1+B14) -> 1986.0642 | D14: 0.00172134 | E14: =E13*(1+D14) -> 1912.5063 | F14: =D14*Varsayımlar!$B$3 -> 0.002151675 | G14: =G13*(1+F14) -> 1889.6176
... A1535: 46295 | B1535: -0.00604751 | C1535: =C1534*(1+B1535) -> 64288.527 | D1535: -0.01009028 | E1535: =E1534*(1+D1535) -> 271909.56 | F1535: =D1535*Varsayımlar!$B$3 -> -0.01261285 | G1535: =G1534*(1+F1535) -> 849378.71

Sheet Varsayımlar
A1: Varsayım | B1: Değer | C1: Not
A2: Başlangıç bakiyesi ($) | B2: 2000 | C2: Kullanıcının sermayesi (~2.000 $).
A3: T60 kaldıraç (sağ sütun) | B3: 1.25 | C3: Değiştirilebilir. 1,25x'te tam dönem düşüş ~ -%25 (madde 437 tablosu).
A4: Başlangıç tarihi | B4: 44762 | C4: Backtest ısınma süresinden sonraki ilk gün.
A5: Bitiş tarihi | B5: 46295 | C5: Veri sonu (Ekim 2026 funding verisi henüz yayınlanmadı).
A8: KAYNAK: binance-carry-bot backtest motoru (g33.py), gerçekçi ağırlık kayması modeli (madde 419),
A9: 2.000 $ seviyesi (D8 evreni), iki dilim hizasının (FAZ_KAY 0/1) günlük getiri ortalaması.
A10: Eski bot = madde 442 öncesi ayarlar (hacim 100M, yaş 90, kâr al 0,40). T60 = madde 442 ile botun yeni varsayılanı.
A11: T60 x kaldıraç sütunu yaklaşıktır: günlük getiri x kaldıraç (teminat maliyeti ve likidasyon modelde yok).
A12: Bunlar BACKTEST sonuçlarıdır, canlı hesabın gerçek getirisi değildir. Gelecek için garanti değildir.
A13: Mavi = girilen veri / varsayım; siyah = formül. Sarı hücreler değiştirilebilir.
