Workbook

Sheet Varsayımlar
A1: 2026 kazanç defteri — varsayımlar
A3: Başlangıç bakiyesi (1 Ocak 2026, $) | B3: 50000 | C3: ← değiştirilebilir (kullanıcının 1-5 milyon TL ≈ 20-100 bin $ aralığından örnek)
A5: Kaynak: binance-carry-bot backtest motoru (g33.py), KAR_HARITASI madde 601 / 623 / 628 / 629. Günlük getiriler 'Günlük' sayfasında (mavi = motor çıktısı).
A6: Model: gerçekçi (canlı gibi tek hesap girişi + işlem başı 5 bp + düzeltilmiş kademe dolumu), iki dilim hizasının ortalaması. Evren: TAM (≳ 12.500 $ bakiye).
A7: T4 = kod varsayılanı, kaldıraçsız. T7K 1,15x ve T6 1,10x: günlük getiri × kaldıraç (T4 ile aynı 6 yıllık maks düşüş, madde 596 yöntemi).
A8: Koşullu stop = CARRY_LONG_24S_PIYASA=0,03 (24 sa long stop yalnız piyasa medyanı ≤ −%3 iken). T6 serisi bot ritminde (8 sa), T7K serisi 4 sa kontrolle (fark ~3 puan/yıl).
A9: Kâr her gün yeniden yatırılır (bileşik). 2026 ölçümü 1 Ocak – 30 Eylül (Ekim verisi henüz yok).
A10: Bunlar geçmiş verinin simülasyonudur; canlı hesabın gerçek sonucu değildir ve gelecek için garanti vermez.

Sheet Özet
A1: 2026 (1 Ocak – 30 Eylül) özet — TAM evren (20-100 bin $)
A3: Ölçü | B3: T4 (şimdiki) | C3: T7K 1,15x + koşullu stop | D3: T6 1,10x + koşullu stop
A4: Başlangıç bakiyesi $ | B4: =Varsayımlar!$B$3 -> 50000 | C4: =Varsayımlar!$B$3 -> 50000 | D4: =Varsayımlar!$B$3 -> 50000
A5: 30 Eylül bakiyesi $ | B5: =Günlük!F274 -> 207232.71 | C5: =Günlük!G274 -> 236679.05 | D5: =Günlük!H274 -> 294431.99
A6: Toplam kâr $ | B6: =Günlük!F274-Varsayımlar!$B$3 -> 157232.71 | C6: =Günlük!G274-Varsayımlar!$B$3 -> 186679.05 | D6: =Günlük!H274-Varsayımlar!$B$3 -> 244431.99
A7: Toplam getiri % | B7: =Günlük!F274/Varsayımlar!$B$3-1 -> 3.1446541 | C7: =Günlük!G274/Varsayımlar!$B$3-1 -> 3.733581 | D7: =Günlük!H274/Varsayımlar!$B$3-1 -> 4.8886398
A8: Ortalama günlük getiri % | B8: =AVERAGE(Günlük!C2:C274) -> 0.0054288559 | C8: =AVERAGE(Günlük!D2:D274) -> 0.005959903 | D8: =AVERAGE(Günlük!E2:E274) -> 0.006826824
A9: En iyi gün % | B9: =MAX(Günlük!C2:C274) -> 0.076510279 | C9: =MAX(Günlük!D2:D274) -> 0.089854281 | D9: =MAX(Günlük!E2:E274) -> 0.085871618
A10: En kötü gün % | B10: =MIN(Günlük!C2:C274) -> -0.052912958 | C10: =MIN(Günlük!D2:D274) -> -0.06337215 | D10: =MIN(Günlük!E2:E274) -> -0.058453663
A11: Kazançlı gün sayısı | B11: =COUNTIF(Günlük!C2:C274,">0") -> 162 | C11: =COUNTIF(Günlük!D2:D274,">0") -> 163 | D11: =COUNTIF(Günlük!E2:E274,">0") -> 165
A12: Zararlı gün sayısı | B12: =COUNTIF(Günlük!C2:C274,"<0") -> 111 | C12: =COUNTIF(Günlük!D2:D274,"<0") -> 110 | D12: =COUNTIF(Günlük!E2:E274,"<0") -> 108
A13: −%3'ten kötü gün | B13: =COUNTIF(Günlük!C2:C274,"<-0.03") -> 9 | C13: =COUNTIF(Günlük!D2:D274,"<-0.03") -> 15 | D13: =COUNTIF(Günlük!E2:E274,"<-0.03") -> 17
A14: −%5'ten kötü gün | B14: =COUNTIF(Günlük!C2:C274,"<-0.05") -> 1 | C14: =COUNTIF(Günlük!D2:D274,"<-0.05") -> 2 | D14: =COUNTIF(Günlük!E2:E274,"<-0.05") -> 1
A15: En kötü hafta % | B15: =MIN(Haftalık!E2:E41) -> -0.064401672 | C15: =MIN(Haftalık!F2:F41) -> -0.094150007 | D15: =MIN(Haftalık!G2:G41) -> -0.11102361
A16: En kötü ay % | B16: =MIN(Aylık!E2:E10) -> 0.043422403 | C16: =MIN(Aylık!F2:F10) -> 0.033837982 | D16: =MIN(Aylık!G2:G10) -> 0.037359872
A17: Zararlı hafta sayısı | B17: =COUNTIF(Haftalık!E2:E41,"<0") -> 13 | C17: =COUNTIF(Haftalık!F2:F41,"<0") -> 10 | D17: =COUNTIF(Haftalık!G2:G41,"<0") -> 10

Sheet Günlük
A1: Tarih | B1: Gün | C1: T4 (şimdiki) günlük % | D1: T7K 1,15x + koşullu stop günlük % | E1: T6 1,10x + koşullu stop günlük % | F1: T4 (şimdiki) bakiye $ | G1: T7K 1,15x + koşullu stop bakiye $ | H1: T6 1,10x + koşullu stop bakiye $ | I1: T4 (şimdiki) günlük kâr $ | J1: T7K 1,15x + koşullu stop günlük kâr $ | K1: T6 1,10x + koşullu stop günlük kâr $
A2: 46023 | B2: Per | C2: -0.006748597 | D2: -0.0042337577 | E2: -0.0075103277 | F2: =Varsayımlar!$B$3*(1+C2) -> 49662.57 | G2: =Varsayımlar!$B$3*(1+D2) -> 49788.312 | H2: =Varsayımlar!$B$3*(1+E2) -> 49624.484 | I2: =F2-Varsayımlar!$B$3 -> -337.42985 | J2: =G2-Varsayımlar!$B$3 -> -211.68788 | K2: =H2-Varsayımlar!$B$3 -> -375.51639
A3: 46024 | B3: Cum | C3: -0.012396018 | D3: -0.014392616 | E3: -0.018769597 | F3: =F2*(1+C3) -> 49046.952 | G3: =G2*(1+D3) -> 49071.728 | H3: =H2*(1+E3) -> 48693.052 | I3: =F3-F2 -> -615.6181 | J3: =G3-G2 -> -716.58408 | K3: =H3-H2 -> -931.43158
A4: 46025 | B4: Cmt | C4: 0.0033575546 | D4: 0.00042162139 | E4: 0.00047576734 | F4: =F3*(1+C4) -> 49211.63 | G4: =G3*(1+D4) -> 49092.418 | H4: =H3*(1+E4) -> 48716.219 | I4: =F4-F3 -> 164.67782 | J4: =G4-G3 -> 20.68969 | K4: =H4-H3 -> 23.166564
A5: 46026 | B5: Paz | C5: 0.0027580819 | D5: 0.0036594662 | E5: 0.001800392 | F5: =F4*(1+C5) -> 49347.36 | G5: =G4*(1+D5) -> 49272.07 | H5: =H4*(1+E5) -> 48803.927 | I5: =F5-F4 -> 135.72971 | J5: =G5-G4 -> 179.65204 | K5: =H5-H4 -> 87.708293
A6: 46027 | B6: Pzt | C6: 0.021343801 | D6: 0.022989845 | E6: 0.020778108 | F6: =F5*(1+C6) -> 50400.62 | G6: =G5*(1+D6) -> 50404.827 | H6: =H5*(1+E6) -> 49817.98 | I6: =F6-F5 -> 1053.2602 | J6: =G6-G5 -> 1132.7572 | K6: =H6-H5 -> 1014.0533
A7: 46028 | B7: Sal | C7: 0.03558653 | D7: 0.041346396 | E7: 0.038102738 | F7: =F6*(1+C7) -> 52194.203 | G7: =G6*(1+D7) -> 52488.885 | H7: =H6*(1+E7) -> 51716.182 | I7: =F7-F6 -> 1793.5832 | J7: =G7-G6 -> 2084.0579 | K7: =H7-H6 -> 1898.2014
A8: 46029 | B8: Çar | C8: -0.0030841681 | D8: -0.001332675 | E8: 0.0051795774 | F8: =F7*(1+C8) -> 52033.227 | G8: =G7*(1+D8) -> 52418.934 | H8: =H7*(1+E8) -> 51984.05 | I8: =F8-F7 -> -160.9757 | J8: =G8-G7 -> -69.950624 | K8: =H8-H7 -> 267.86797
A9: 46030 | B9: Per | C9: 0.0035848839 | D9: 0.0073474643 | E9: 0.011577841 | F9: =F8*(1+C9) -> 52219.76 | G9: =G8*(1+D9) -> 52804.081 | H9: =H8*(1+E9) -> 52585.913 | I9: =F9-F8 -> 186.53308 | J9: =G9-G8 -> 385.14625 | K9: =H9-H8 -> 601.86304
A10: 46031 | B10: Cum | C10: -0.0062668818 | D10: -0.0064317795 | E10: -0.0050985889 | F10: =F9*(1+C10) -> 51892.505 | G10: =G9*(1+D10) -> 52464.456 | H10: =H9*(1+E10) -> 52317.799 | I10: =F10-F9 -> -327.25507 | J10: =G10-G9 -> -339.6242 | K10: =H10-H9 -> -268.11395
A11: 46032 | B11: Cmt | C11: 0.0011728723 | D11: -0.0010744851 | E11: -0.00055251149 | F11: =F10*(1+C11) -> 51953.369 | G11: =G10*(1+D11) -> 52408.084 | H11: =H10*(1+E11) -> 52288.892 | I11: =F11-F10 -> 60.863281 | J11: =G11-G10 -> -56.372279 | K11: =H11-H10 -> -28.906185
A12: 46033 | B12: Paz | C12: 0.031111599 | D12: 0.036873217 | E12: 0.034784875 | F12: =F11*(1+C12) -> 53569.721 | G12: =G11*(1+D12) -> 54340.539 | H12: =H11*(1+E12) -> 54107.755 | I12: =F12-F11 -> 1616.3524 | J12: =G12-G11 -> 1932.4546 | K12: =H12-H11 -> 1818.8626
A13: 46034 | B13: Pzt | C13: 0.0085210808 | D13: 0.012118744 | E13: 0.013784522 | F13: =F12*(1+C13) -> 54026.193 | G13: =G12*(1+D13) -> 54999.078 | H13: =H12*(1+E13) -> 54853.605 | I13: =F13-F12 -> 456.47192 | J13: =G13-G12 -> 658.53906 | K13: =H13-H12 -> 745.84954
A14: 46035 | B14: Sal | C14: 0.0052130695 | D14: 0.0057246633 | E14: -0.00010105634 | F14: =F13*(1+C14) -> 54307.835 | G14: =G13*(1+D14) -> 55313.929 | H14: =H13*(1+E14) -> 54848.061 | I14: =F14-F13 -> 281.6423 | J14: =G14-G13 -> 314.8512 | K14: =H14-H13 -> -5.5433043
... A274: 46295 | B274: Çar | C274: -0.0079479804 | D274: -0.0029248695 | E274: -0.0041254146 | F274: =F273*(1+C274) -> 207232.71 | G274: =G273*(1+D274) -> 236679.05 | H274: =H273*(1+E274) -> 294431.99 | I274: =F274-F273 -> -1660.2774 | J274: =G274-G273 -> -694.28602 | K274: =H274-H273 -> -1219.6858

Sheet Haftalık
A1: Hafta | B1: Başlangıç | C1: Bitiş | D1: Gün | E1: T4 (şimdiki) getiri % | F1: T7K 1,15x + koşullu stop getiri % | G1: T6 1,10x + koşullu stop getiri % | H1: T4 (şimdiki) kâr $ | I1: T7K 1,15x + koşullu stop kâr $ | J1: T6 1,10x + koşullu stop kâr $ | K1: T4 (şimdiki) dönem sonu bakiye $ | L1: T7K 1,15x + koşullu stop dönem sonu bakiye $ | M1: T6 1,10x + koşullu stop dönem sonu bakiye $
A2: 29.12 haftası | B2: =Günlük!A2 -> 46023 | C2: =Günlük!A5 -> 46026 | D2: 4 | E2: =Günlük!F5/Varsayımlar!$B$3-1 -> -0.013052808 | F2: =Günlük!G5/Varsayımlar!$B$3-1 -> -0.014558605 | G2: =Günlük!H5/Varsayımlar!$B$3-1 -> -0.023921462 | H2: =Günlük!F5-Varsayımlar!$B$3 -> -652.64042 | I2: =Günlük!G5-Varsayımlar!$B$3 -> -727.93023 | J2: =Günlük!H5-Varsayımlar!$B$3 -> -1196.0731 | K2: =Günlük!F5 -> 49347.36 | L2: =Günlük!G5 -> 49272.07 | M2: =Günlük!H5 -> 48803.927
A3: 05.01 haftası | B3: =Günlük!A6 -> 46027 | C3: =Günlük!A12 -> 46033 | D3: 7 | E3: =Günlük!F12/Günlük!F5-1 -> 0.085564079 | F3: =Günlük!G12/Günlük!G5-1 -> 0.10286698 | G3: =Günlük!H12/Günlük!H5-1 -> 0.10867626 | H3: =Günlük!F12-Günlük!F5 -> 4222.3614 | I3: =Günlük!G12-Günlük!G5 -> 5068.4689 | J3: =Günlük!H12-Günlük!H5 -> 5303.8282 | K3: =Günlük!F12 -> 53569.721 | L3: =Günlük!G12 -> 54340.539 | M3: =Günlük!H12 -> 54107.755
A4: 12.01 haftası | B4: =Günlük!A13 -> 46034 | C4: =Günlük!A19 -> 46040 | D4: 7 | E4: =Günlük!F19/Günlük!F12-1 -> 0.096804892 | F4: =Günlük!G19/Günlük!G12-1 -> 0.11356242 | G4: =Günlük!H19/Günlük!H12-1 -> 0.11284601 | H4: =Günlük!F19-Günlük!F12 -> 5185.811 | I4: =Günlük!G19-Günlük!G12 -> 6171.0429 | J4: =Günlük!H19-Günlük!H12 -> 6105.8441 | K4: =Günlük!F19 -> 58755.532 | L4: =Günlük!G19 -> 60511.582 | M4: =Günlük!H19 -> 60213.599
A5: 19.01 haftası | B5: =Günlük!A20 -> 46041 | C5: =Günlük!A26 -> 46047 | D5: 7 | E5: =Günlük!F26/Günlük!F19-1 -> 0.17303217 | F5: =Günlük!G26/Günlük!G19-1 -> 0.15504957 | G5: =Günlük!H26/Günlük!H19-1 -> 0.16086807 | H5: =Günlük!F26-Günlük!F19 -> 10166.597 | I5: =Günlük!G26-Günlük!G19 -> 9382.2947 | J5: =Günlük!H26-Günlük!H19 -> 9686.4454 | K5: =Günlük!F26 -> 68922.129 | L5: =Günlük!G26 -> 69893.876 | M5: =Günlük!H26 -> 69900.045
A6: 26.01 haftası | B6: =Günlük!A27 -> 46048 | C6: =Günlük!A33 -> 46054 | D6: 7 | E6: =Günlük!F33/Günlük!F26-1 -> -0.0017987054 | F6: =Günlük!G33/Günlük!G26-1 -> 0.0064633838 | G6: =Günlük!H33/Günlük!H26-1 -> 0.021383403 | H6: =Günlük!F33-Günlük!F26 -> -123.97061 | I6: =Günlük!G33-Günlük!G26 -> 451.75095 | J6: =Günlük!H33-Günlük!H26 -> 1494.7008 | K6: =Günlük!F33 -> 68798.158 | L6: =Günlük!G33 -> 70345.627 | M6: =Günlük!H33 -> 71394.745
A7: 02.02 haftası | B7: =Günlük!A34 -> 46055 | C7: =Günlük!A40 -> 46061 | D7: 7 | E7: =Günlük!F40/Günlük!F33-1 -> 0.033710874 | F7: =Günlük!G40/Günlük!G33-1 -> 0.04883214 | G7: =Günlük!H40/Günlük!H33-1 -> 0.063590263 | H7: =Günlük!F40-Günlük!F33 -> 2319.246 | I7: =Günlük!G40-Günlük!G33 -> 3435.1275 | J7: =Günlük!H40-Günlük!H33 -> 4540.0106 | K7: =Günlük!F40 -> 71117.404 | L7: =Günlük!G40 -> 73780.755 | M7: =Günlük!H40 -> 75934.756
A8: 09.02 haftası | B8: =Günlük!A41 -> 46062 | C8: =Günlük!A47 -> 46068 | D8: 7 | E8: =Günlük!F47/Günlük!F40-1 -> 0.040458326 | F8: =Günlük!G47/Günlük!G40-1 -> 0.059013282 | G8: =Günlük!H47/Günlük!H40-1 -> 0.054212916 | H8: =Günlük!F47-Günlük!F40 -> 2877.2911 | I8: =Günlük!G47-Günlük!G40 -> 4354.0445 | J8: =Günlük!H47-Günlük!H40 -> 4116.6446 | K8: =Günlük!F47 -> 73994.696 | L8: =Günlük!G47 -> 78134.799 | M8: =Günlük!H47 -> 80051.401
A9: 16.02 haftası | B9: =Günlük!A48 -> 46069 | C9: =Günlük!A54 -> 46075 | D9: 7 | E9: =Günlük!F54/Günlük!F47-1 -> -0.015498044 | F9: =Günlük!G54/Günlük!G47-1 -> -0.0079256799 | G9: =Günlük!H54/Günlük!H47-1 -> -0.011913676 | H9: =Günlük!F54-Günlük!F47 -> -1146.7731 | I9: =Günlük!G54-Günlük!G47 -> -619.27141 | J9: =Günlük!H54-Günlük!H47 -> -953.70643 | K9: =Günlük!F54 -> 72847.922 | L9: =Günlük!G54 -> 77515.528 | M9: =Günlük!H54 -> 79097.694
A10: 23.02 haftası | B10: =Günlük!A55 -> 46076 | C10: =Günlük!A61 -> 46082 | D10: 7 | E10: =Günlük!F61/Günlük!F54-1 -> 0.12333767 | F10: =Günlük!G61/Günlük!G54-1 -> 0.14867498 | G10: =Günlük!H61/Günlük!H54-1 -> 0.15703835 | H10: =Günlük!F61-Günlük!F54 -> 8984.8932 | I10: =Günlük!G61-Günlük!G54 -> 11524.62 | J10: =Günlük!H61-Günlük!H54 -> 12421.371 | K10: =Günlük!F61 -> 81832.816 | L10: =Günlük!G61 -> 89040.147 | M10: =Günlük!H61 -> 91519.066
A11: 02.03 haftası | B11: =Günlük!A62 -> 46083 | C11: =Günlük!A68 -> 46089 | D11: 7 | E11: =Günlük!F68/Günlük!F61-1 -> 0.055926505 | F11: =Günlük!G68/Günlük!G61-1 -> 0.058404842 | G11: =Günlük!H68/Günlük!H61-1 -> 0.050495398 | H11: =Günlük!F68-Günlük!F61 -> 4576.6234 | I11: =Günlük!G68-Günlük!G61 -> 5200.3757 | J11: =Günlük!H68-Günlük!H61 -> 4621.2916 | K11: =Günlük!F68 -> 86409.439 | L11: =Günlük!G68 -> 94240.523 | M11: =Günlük!H68 -> 96140.357
A12: 09.03 haftası | B12: =Günlük!A69 -> 46090 | C12: =Günlük!A75 -> 46096 | D12: 7 | E12: =Günlük!F75/Günlük!F68-1 -> -0.048037862 | F12: =Günlük!G75/Günlük!G68-1 -> -0.063761022 | G12: =Günlük!H75/Günlük!H68-1 -> -0.061292512 | H12: =Günlük!F75-Günlük!F68 -> -4150.9247 | I12: =Günlük!G75-Günlük!G68 -> -6008.8721 | J12: =Günlük!H75-Günlük!H68 -> -5892.684 | K12: =Günlük!F75 -> 82258.514 | L12: =Günlük!G75 -> 88231.651 | M12: =Günlük!H75 -> 90247.673
A13: 16.03 haftası | B13: =Günlük!A76 -> 46097 | C13: =Günlük!A82 -> 46103 | D13: 7 | E13: =Günlük!F82/Günlük!F75-1 -> 0.15103276 | F13: =Günlük!G82/Günlük!G75-1 -> 0.1380171 | G13: =Günlük!H82/Günlük!H75-1 -> 0.14874026 | H13: =Günlük!F82-Günlük!F75 -> 12423.73 | I13: =Günlük!G82-Günlük!G75 -> 12177.476 | J13: =Günlük!H82-Günlük!H75 -> 13423.463 | K13: =Günlük!F82 -> 94682.245 | L13: =Günlük!G82 -> 100409.13 | M13: =Günlük!H82 -> 103671.14
A14: 23.03 haftası | B14: =Günlük!A83 -> 46104 | C14: =Günlük!A89 -> 46110 | D14: 7 | E14: =Günlük!F89/Günlük!F82-1 -> -0.017571208 | F14: =Günlük!G89/Günlük!G82-1 -> 0.021990498 | G14: =Günlük!H89/Günlük!H82-1 -> 0.022452499 | H14: =Günlük!F89-Günlük!F82 -> -1663.6814 | I14: =Günlük!G89-Günlük!G82 -> 2208.0467 | J14: =Günlük!H89-Günlük!H82 -> 2327.676 | K14: =Günlük!F89 -> 93018.563 | L14: =Günlük!G89 -> 102617.17 | M14: =Günlük!H89 -> 105998.81
A15: 30.03 haftası | B15: =Günlük!A90 -> 46111 | C15: =Günlük!A96 -> 46117 | D15: 7 | E15: =Günlük!F96/Günlük!F89-1 -> -0.049885846 | F15: =Günlük!G96/Günlük!G89-1 -> -0.063377349 | G15: =Günlük!H96/Günlük!H89-1 -> -0.077192421 | H15: =Günlük!F96-Günlük!F89 -> -4640.3097 | I15: =Günlük!G96-Günlük!G89 -> -6503.6045 | J15: =Günlük!H96-Günlük!H89 -> -8182.3049 | K15: =Günlük!F96 -> 88378.253 | L15: =Günlük!G96 -> 96113.57 | M15: =Günlük!H96 -> 97816.507
A16: 06.04 haftası | B16: =Günlük!A97 -> 46118 | C16: =Günlük!A103 -> 46124 | D16: 7 | E16: =Günlük!F103/Günlük!F96-1 -> 0.015198607 | F16: =Günlük!G103/Günlük!G96-1 -> 0.089816062 | G16: =Günlük!H103/Günlük!H96-1 -> 0.094138834 | H16: =Günlük!F103-Günlük!F96 -> 1343.2263 | I16: =Günlük!G103-Günlük!G96 -> 8632.5423 | J16: =Günlük!H103-Günlük!H96 -> 9208.3319 | K16: =Günlük!F103 -> 89721.48 | L16: =Günlük!G103 -> 104746.11 | M16: =Günlük!H103 -> 107024.84
A17: 13.04 haftası | B17: =Günlük!A104 -> 46125 | C17: =Günlük!A110 -> 46131 | D17: 7 | E17: =Günlük!F110/Günlük!F103-1 -> 0.15393816 | F17: =Günlük!G110/Günlük!G103-1 -> 0.1578329 | G17: =Günlük!H110/Günlük!H103-1 -> 0.15135751 | H17: =Günlük!F110-Günlük!F103 -> 13811.559 | I17: =Günlük!G110-Günlük!G103 -> 16532.382 | J17: =Günlük!H110-Günlük!H103 -> 16199.013 | K17: =Günlük!F110 -> 103533.04 | L17: =Günlük!G110 -> 121278.49 | M17: =Günlük!H110 -> 123223.85
A18: 20.04 haftası | B18: =Günlük!A111 -> 46132 | C18: =Günlük!A117 -> 46138 | D18: 7 | E18: =Günlük!F117/Günlük!F110-1 -> 0.041617748 | F18: =Günlük!G117/Günlük!G110-1 -> 0.03776739 | G18: =Günlük!H117/Günlük!H110-1 -> 0.037372444 | H18: =Günlük!F117-Günlük!F110 -> 4308.8119 | I18: =Günlük!G117-Günlük!G110 -> 4580.3722 | J18: =Günlük!H117-Günlük!H110 -> 4605.1765 | K18: =Günlük!F117 -> 107841.85 | L18: =Günlük!G117 -> 125858.87 | M18: =Günlük!H117 -> 127829.03
A19: 27.04 haftası | B19: =Günlük!A118 -> 46139 | C19: =Günlük!A124 -> 46145 | D19: 7 | E19: =Günlük!F124/Günlük!F117-1 -> 0.069223601 | F19: =Günlük!G124/Günlük!G117-1 -> 0.081039476 | G19: =Günlük!H124/Günlük!H117-1 -> 0.084840205 | H19: =Günlük!F124-Günlük!F117 -> 7465.2013 | I19: =Günlük!G124-Günlük!G117 -> 10199.537 | J19: =Günlük!H124-Günlük!H117 -> 10845.041 | K19: =Günlük!F124 -> 115307.05 | L19: =Günlük!G124 -> 136058.4 | M19: =Günlük!H124 -> 138674.07
A20: 04.05 haftası | B20: =Günlük!A125 -> 46146 | C20: =Günlük!A131 -> 46152 | D20: 7 | E20: =Günlük!F131/Günlük!F124-1 -> 0.067931705 | F20: =Günlük!G131/Günlük!G124-1 -> 0.059176973 | G20: =Günlük!H131/Günlük!H124-1 -> 0.050899612 | H20: =Günlük!F131-Günlük!F124 -> 7833.0046 | I20: =Günlük!G131-Günlük!G124 -> 8051.5245 | J20: =Günlük!H131-Günlük!H124 -> 7058.4563 | K20: =Günlük!F131 -> 123140.06 | L20: =Günlük!G131 -> 144109.93 | M20: =Günlük!H131 -> 145732.53
A21: 11.05 haftası | B21: =Günlük!A132 -> 46153 | C21: =Günlük!A138 -> 46159 | D21: 7 | E21: =Günlük!F138/Günlük!F131-1 -> -0.028094986 | F21: =Günlük!G138/Günlük!G131-1 -> -0.022704189 | G21: =Günlük!H138/Günlük!H131-1 -> -0.026623044 | H21: =Günlük!F138-Günlük!F131 -> -3459.6181 | I21: =Günlük!G138-Günlük!G131 -> -3271.899 | J21: =Günlük!H138-Günlük!H131 -> -3879.8434 | K21: =Günlük!F138 -> 119680.44 | L21: =Günlük!G138 -> 140838.03 | M21: =Günlük!H138 -> 141852.68
A22: 18.05 haftası | B22: =Günlük!A139 -> 46160 | C22: =Günlük!A145 -> 46166 | D22: 7 | E22: =Günlük!F145/Günlük!F138-1 -> 0.082812458 | F22: =Günlük!G145/Günlük!G138-1 -> 0.066431048 | G22: =Günlük!H145/Günlük!H138-1 -> 0.087831357 | H22: =Günlük!F145-Günlük!F138 -> 9911.0313 | I22: =Günlük!G145-Günlük!G138 -> 9356.0179 | J22: =Günlük!H145-Günlük!H138 -> 12459.114 | K22: =Günlük!F145 -> 129591.47 | L22: =Günlük!G145 -> 150194.05 | M22: =Günlük!H145 -> 154311.8
A23: 25.05 haftası | B23: =Günlük!A146 -> 46167 | C23: =Günlük!A152 -> 46173 | D23: 7 | E23: =Günlük!F152/Günlük!F145-1 -> 0.022174018 | F23: =Günlük!G152/Günlük!G145-1 -> 0.034298426 | G23: =Günlük!H152/Günlük!H145-1 -> 0.045804605 | H23: =Günlük!F152-Günlük!F145 -> 2873.5635 | I23: =Günlük!G152-Günlük!G145 -> 5151.4195 | J23: =Günlük!H152-Günlük!H145 -> 7068.1909 | K23: =Günlük!F152 -> 132465.03 | L23: =Günlük!G152 -> 155345.47 | M23: =Günlük!H152 -> 161379.99
A24: 01.06 haftası | B24: =Günlük!A153 -> 46174 | C24: =Günlük!A159 -> 46180 | D24: 7 | E24: =Günlük!F159/Günlük!F152-1 -> 0.033767283 | F24: =Günlük!G159/Günlük!G152-1 -> 0.073652365 | G24: =Günlük!H159/Günlük!H152-1 -> 0.099719639 | H24: =Günlük!F159-Günlük!F152 -> 4472.9843 | I24: =Günlük!G159-Günlük!G152 -> 11441.561 | J24: =Günlük!H159-Günlük!H152 -> 16092.754 | K24: =Günlük!F159 -> 136938.02 | L24: =Günlük!G159 -> 166787.03 | M24: =Günlük!H159 -> 177472.74
A25: 08.06 haftası | B25: =Günlük!A160 -> 46181 | C25: =Günlük!A166 -> 46187 | D25: 7 | E25: =Günlük!F166/Günlük!F159-1 -> -0.0055321956 | F25: =Günlük!G166/Günlük!G159-1 -> -0.0084272671 | G25: =Günlük!H166/Günlük!H159-1 -> -0.00013601637 | H25: =Günlük!F166-Günlük!F159 -> -757.5679 | I25: =Günlük!G166-Günlük!G159 -> -1405.5588 | J25: =Günlük!H166-Günlük!H159 -> -24.139198 | K25: =Günlük!F166 -> 136180.45 | L25: =Günlük!G166 -> 165381.47 | M25: =Günlük!H166 -> 177448.6
A26: 15.06 haftası | B26: =Günlük!A167 -> 46188 | C26: =Günlük!A173 -> 46194 | D26: 7 | E26: =Günlük!F173/Günlük!F166-1 -> 0.0083495143 | F26: =Günlük!G173/Günlük!G166-1 -> 0.019997737 | G26: =Günlük!H173/Günlük!H166-1 -> 0.042977681 | H26: =Günlük!F173-Günlük!F166 -> 1137.0406 | I26: =Günlük!G173-Günlük!G166 -> 3307.255 | J26: =Günlük!H173-Günlük!H166 -> 7626.3293 | K26: =Günlük!F173 -> 137317.49 | L26: =Günlük!G173 -> 168688.72 | M26: =Günlük!H173 -> 185074.93
A27: 22.06 haftası | B27: =Günlük!A174 -> 46195 | C27: =Günlük!A180 -> 46201 | D27: 7 | E27: =Günlük!F180/Günlük!F173-1 -> 0.11901532 | F27: =Günlük!G180/Günlük!G173-1 -> 0.071077538 | G27: =Günlük!H180/Günlük!H173-1 -> 0.097896329 | H27: =Günlük!F180-Günlük!F173 -> 16342.885 | I27: =Günlük!G180-Günlük!G173 -> 11989.979 | J27: =Günlük!H180-Günlük!H173 -> 18118.156 | K27: =Günlük!F180 -> 153660.38 | L27: =Günlük!G180 -> 180678.7 | M27: =Günlük!H180 -> 203193.09
A28: 29.06 haftası | B28: =Günlük!A181 -> 46202 | C28: =Günlük!A187 -> 46208 | D28: 7 | E28: =Günlük!F187/Günlük!F180-1 -> -0.00064961264 | F28: =Günlük!G187/Günlük!G180-1 -> 0.038512299 | G28: =Günlük!H187/Günlük!H180-1 -> 0.054168679 | H28: =Günlük!F187-Günlük!F180 -> -99.819722 | I28: =Günlük!G187-Günlük!G180 -> 6958.3522 | J28: =Günlük!H187-Günlük!H180 -> 11006.701 | K28: =Günlük!F187 -> 153560.56 | L28: =Günlük!G187 -> 187637.05 | M28: =Günlük!H187 -> 214199.79
A29: 06.07 haftası | B29: =Günlük!A188 -> 46209 | C29: =Günlük!A194 -> 46215 | D29: 7 | E29: =Günlük!F194/Günlük!F187-1 -> -0.0054370397 | F29: =Günlük!G194/Günlük!G187-1 -> -0.017337638 | G29: =Günlük!H194/Günlük!H187-1 -> -0.033985411 | H29: =Günlük!F194-Günlük!F187 -> -834.91484 | I29: =Günlük!G194-Günlük!G187 -> -3253.1833 | J29: =Günlük!H194-Günlük!H187 -> -7279.668 | K29: =Günlük!F194 -> 152725.64 | L29: =Günlük!G194 -> 184383.87 | M29: =Günlük!H194 -> 206920.12
A30: 13.07 haftası | B30: =Günlük!A195 -> 46216 | C30: =Günlük!A201 -> 46222 | D30: 7 | E30: =Günlük!F201/Günlük!F194-1 -> 0.073599694 | F30: =Günlük!G201/Günlük!G194-1 -> 0.051221146 | G30: =Günlük!H201/Günlük!H194-1 -> 0.073586118 | H30: =Günlük!F201-Günlük!F194 -> 11240.561 | I30: =Günlük!G201-Günlük!G194 -> 9444.3532 | J30: =Günlük!H201-Günlük!H194 -> 15226.449 | K30: =Günlük!F201 -> 163966.2 | L30: =Günlük!G201 -> 193828.22 | M30: =Günlük!H201 -> 222146.57
A31: 20.07 haftası | B31: =Günlük!A202 -> 46223 | C31: =Günlük!A208 -> 46229 | D31: 7 | E31: =Günlük!F208/Günlük!F201-1 -> 0.0023573308 | F31: =Günlük!G208/Günlük!G201-1 -> 0.003711043 | G31: =Günlük!H208/Günlük!H201-1 -> 0.0059179096 | H31: =Günlük!F208-Günlük!F201 -> 386.52258 | I31: =Günlük!G208-Günlük!G201 -> 719.30487 | J31: =Günlük!H208-Günlük!H201 -> 1314.6433 | K31: =Günlük!F208 -> 164352.72 | L31: =Günlük!G208 -> 194547.53 | M31: =Günlük!H208 -> 223461.21
A32: 27.07 haftası | B32: =Günlük!A209 -> 46230 | C32: =Günlük!A215 -> 46236 | D32: 7 | E32: =Günlük!F215/Günlük!F208-1 -> 0.03170986 | F32: =Günlük!G215/Günlük!G208-1 -> 0.017624192 | G32: =Günlük!H215/Günlük!H208-1 -> 0.018362854 | H32: =Günlük!F215-Günlük!F208 -> 5211.6019 | I32: =Günlük!G215-Günlük!G208 -> 3428.743 | J32: =Günlük!H215-Günlük!H208 -> 4103.3857 | K32: =Günlük!F215 -> 169564.33 | L32: =Günlük!G215 -> 197976.27 | M32: =Günlük!H215 -> 227564.6
A33: 03.08 haftası | B33: =Günlük!A216 -> 46237 | C33: =Günlük!A222 -> 46243 | D33: 7 | E33: =Günlük!F222/Günlük!F215-1 -> 0.068701479 | F33: =Günlük!G222/Günlük!G215-1 -> 0.05372053 | G33: =Günlük!H222/Günlük!H215-1 -> 0.055014515 | H33: =Günlük!F222-Günlük!F215 -> 11649.32 | I33: =Günlük!G222-Günlük!G215 -> 10635.39 | J33: =Günlük!H222-Günlük!H215 -> 12519.356 | K33: =Günlük!F222 -> 181213.65 | L33: =Günlük!G222 -> 208611.66 | M33: =Günlük!H222 -> 240083.95
A34: 10.08 haftası | B34: =Günlük!A223 -> 46244 | C34: =Günlük!A229 -> 46250 | D34: 7 | E34: =Günlük!F229/Günlük!F222-1 -> -0.064401672 | F34: =Günlük!G229/Günlük!G222-1 -> -0.094150007 | G34: =Günlük!H229/Günlük!H222-1 -> -0.11102361 | H34: =Günlük!F229-Günlük!F222 -> -11670.462 | I34: =Günlük!G229-Günlük!G222 -> -19640.789 | J34: =Günlük!H229-Günlük!H222 -> -26654.987 | K34: =Günlük!F229 -> 169543.19 | L34: =Günlük!G229 -> 188970.87 | M34: =Günlük!H229 -> 213428.97
A35: 17.08 haftası | B35: =Günlük!A230 -> 46251 | C35: =Günlük!A236 -> 46257 | D35: 7 | E35: =Günlük!F236/Günlük!F229-1 -> -0.0036353064 | F35: =Günlük!G236/Günlük!G229-1 -> 0.027544824 | G35: =Günlük!H236/Günlük!H229-1 -> 0.046717703 | H35: =Günlük!F236-Günlük!F229 -> -616.34142 | I35: =Günlük!G236-Günlük!G229 -> 5205.1695 | J35: =Günlük!H236-Günlük!H229 -> 9970.911 | K35: =Günlük!F236 -> 168926.84 | L35: =Günlük!G236 -> 194176.04 | M35: =Günlük!H236 -> 223399.88
A36: 24.08 haftası | B36: =Günlük!A237 -> 46258 | C36: =Günlük!A243 -> 46264 | D36: 7 | E36: =Günlük!F243/Günlük!F236-1 -> 0.10395549 | F36: =Günlük!G243/Günlük!G236-1 -> 0.10505534 | G36: =Günlük!H243/Günlük!H236-1 -> 0.14185475 | H36: =Günlük!F243-Günlük!F236 -> 17560.872 | I36: =Günlük!G243-Günlük!G236 -> 20399.229 | J36: =Günlük!H243-Günlük!H236 -> 31690.334 | K36: =Günlük!F243 -> 186487.72 | L36: =Günlük!G243 -> 214575.27 | M36: =Günlük!H243 -> 255090.21
A37: 31.08 haftası | B37: =Günlük!A244 -> 46265 | C37: =Günlük!A250 -> 46271 | D37: 7 | E37: =Günlük!F250/Günlük!F243-1 -> 0.014611573 | F37: =Günlük!G250/Günlük!G243-1 -> -0.010171623 | G37: =Günlük!H250/Günlük!H243-1 -> -0.015837655 | H37: =Günlük!F250-Günlük!F243 -> 2724.8789 | I37: =Günlük!G250-Günlük!G243 -> -2182.5787 | J37: =Günlük!H250-Günlük!H243 -> -4040.0309 | K37: =Günlük!F250 -> 189212.59 | L37: =Günlük!G250 -> 212392.69 | M37: =Günlük!H250 -> 251050.18
A38: 07.09 haftası | B38: =Günlük!A251 -> 46272 | C38: =Günlük!A257 -> 46278 | D38: 7 | E38: =Günlük!F257/Günlük!F250-1 -> 0.085496974 | F38: =Günlük!G257/Günlük!G250-1 -> 0.071101261 | G38: =Günlük!H257/Günlük!H250-1 -> 0.09868313 | H38: =Günlük!F257-Günlük!F250 -> 16177.104 | I38: =Günlük!G257-Günlük!G250 -> 15101.388 | J38: =Günlük!H257-Günlük!H250 -> 24774.418 | K38: =Günlük!F257 -> 205389.7 | L38: =Günlük!G257 -> 227494.08 | M38: =Günlük!H257 -> 275824.6
A39: 14.09 haftası | B39: =Günlük!A258 -> 46279 | C39: =Günlük!A264 -> 46285 | D39: 7 | E39: =Günlük!F264/Günlük!F257-1 -> 0.042369974 | F39: =Günlük!G264/Günlük!G257-1 -> 0.058773761 | G39: =Günlük!H264/Günlük!H257-1 -> 0.080483985 | H39: =Günlük!F264-Günlük!F257 -> 8702.3563 | I39: =Günlük!G264-Günlük!G257 -> 13370.683 | J39: =Günlük!H264-Günlük!H257 -> 22199.463 | K39: =Günlük!F264 -> 214092.06 | L39: =Günlük!G264 -> 240864.76 | M39: =Günlük!H264 -> 298024.06
A40: 21.09 haftası | B40: =Günlük!A265 -> 46286 | C40: =Günlük!A271 -> 46292 | D40: 7 | E40: =Günlük!F271/Günlük!F264-1 -> -0.048265919 | F40: =Günlük!G271/Günlük!G264-1 -> -0.035937922 | G40: =Günlük!H271/Günlük!H264-1 -> -0.044217802 | H40: =Günlük!F271-Günlük!F264 -> -10333.35 | I40: =Günlük!G271-Günlük!G264 -> -8656.1791 | J40: =Günlük!H271-Günlük!H264 -> -13177.969 | K40: =Günlük!F271 -> 203758.71 | L40: =Günlük!G271 -> 232208.59 | M40: =Günlük!H271 -> 284846.09
...

Sheet Aylık
A1: Ay | B1: Başlangıç | C1: Bitiş | D1: Gün | E1: T4 (şimdiki) getiri % | F1: T7K 1,15x + koşullu stop getiri % | G1: T6 1,10x + koşullu stop getiri % | H1: T4 (şimdiki) kâr $ | I1: T7K 1,15x + koşullu stop kâr $ | J1: T6 1,10x + koşullu stop kâr $ | K1: T4 (şimdiki) dönem sonu bakiye $ | L1: T7K 1,15x + koşullu stop dönem sonu bakiye $ | M1: T6 1,10x + koşullu stop dönem sonu bakiye $
A2: Ocak 2026 | B2: =Günlük!A2 -> 46023 | C2: =Günlük!A32 -> 46053 | D2: 31 | E2: =Günlük!F32/Varsayımlar!$B$3-1 -> 0.37122495 | F2: =Günlük!G32/Varsayımlar!$B$3-1 -> 0.43876901 | G2: =Günlük!H32/Varsayımlar!$B$3-1 -> 0.45663581 | H2: =Günlük!F32-Varsayımlar!$B$3 -> 18561.248 | I2: =Günlük!G32-Varsayımlar!$B$3 -> 21938.451 | J2: =Günlük!H32-Varsayımlar!$B$3 -> 22831.791 | K2: =Günlük!F32 -> 68561.248 | L2: =Günlük!G32 -> 71938.451 | M2: =Günlük!H32 -> 72831.791
A3: Şubat 2026 | B3: =Günlük!A33 -> 46054 | C3: =Günlük!A60 -> 46081 | D3: 28 | E3: =Günlük!F60/Günlük!F32-1 -> 0.18070702 | F3: =Günlük!G60/Günlük!G32-1 -> 0.22808526 | G3: =Günlük!H60/Günlük!H32-1 -> 0.24348763 | H3: =Günlük!F60-Günlük!F32 -> 12389.499 | I3: =Günlük!G60-Günlük!G32 -> 16408.1 | J3: =Günlük!H60-Günlük!H32 -> 17733.64 | K3: =Günlük!F60 -> 80950.747 | L3: =Günlük!G60 -> 88346.551 | M3: =Günlük!H60 -> 90565.431
A4: Mart 2026 | B4: =Günlük!A61 -> 46082 | C4: =Günlük!A91 -> 46112 | D4: 31 | E4: =Günlük!F91/Günlük!F60-1 -> 0.10190587 | F4: =Günlük!G91/Günlük!G60-1 -> 0.081819069 | G4: =Günlük!H91/Günlük!H60-1 -> 0.090159152 | H4: =Günlük!F91-Günlük!F60 -> 8249.3564 | I4: =Günlük!G91-Günlük!G60 -> 7228.4325 | J4: =Günlük!H91-Günlük!H60 -> 8165.3024 | K4: =Günlük!F91 -> 89200.103 | L4: =Günlük!G91 -> 95574.983 | M4: =Günlük!H91 -> 98730.733
A5: Nisan 2026 | B5: =Günlük!A92 -> 46113 | C5: =Günlük!A121 -> 46142 | D5: 30 | E5: =Günlük!F121/Günlük!F91-1 -> 0.26091311 | F5: =Günlük!G121/Günlük!G91-1 -> 0.38646912 | G5: =Günlük!H121/Günlük!H91-1 -> 0.36698636 | H5: =Günlük!F121-Günlük!F91 -> 23273.477 | I5: =Günlük!G121-Günlük!G91 -> 36936.78 | J5: =Günlük!H121-Günlük!H91 -> 36232.833 | K5: =Günlük!F121 -> 112473.58 | L5: =Günlük!G121 -> 132511.76 | M5: =Günlük!H121 -> 134963.57
A6: Mayıs 2026 | B6: =Günlük!A122 -> 46143 | C6: =Günlük!A152 -> 46173 | D6: 31 | E6: =Günlük!F152/Günlük!F121-1 -> 0.17774356 | F6: =Günlük!G152/Günlük!G121-1 -> 0.17231453 | G6: =Günlük!H152/Günlük!H121-1 -> 0.19573001 | H6: =Günlük!F152-Günlük!F121 -> 19991.454 | I6: =Günlük!G152-Günlük!G121 -> 22833.703 | J6: =Günlük!H152-Günlük!H121 -> 26416.421 | K6: =Günlük!F152 -> 132465.03 | L6: =Günlük!G152 -> 155345.47 | M6: =Günlük!H152 -> 161379.99
A7: Haziran 2026 | B7: =Günlük!A153 -> 46174 | C7: =Günlük!A182 -> 46203 | D7: 30 | E7: =Günlük!F182/Günlük!F152-1 -> 0.21616033 | F7: =Günlük!G182/Günlük!G152-1 -> 0.22156875 | G7: =Günlük!H182/Günlük!H152-1 -> 0.35052577 | H7: =Günlük!F182-Günlük!F152 -> 28633.686 | I7: =Günlük!G182-Günlük!G152 -> 34419.701 | J7: =Günlük!H182-Günlük!H152 -> 56567.843 | K7: =Günlük!F182 -> 161098.72 | L7: =Günlük!G182 -> 189765.17 | M7: =Günlük!H182 -> 217947.83
A8: Temmuz 2026 | B8: =Günlük!A183 -> 46204 | C8: =Günlük!A213 -> 46234 | D8: 31 | E8: =Günlük!F213/Günlük!F182-1 -> 0.043422403 | F8: =Günlük!G213/Günlük!G182-1 -> 0.033837982 | G8: =Günlük!H213/Günlük!H182-1 -> 0.037359872 | H8: =Günlük!F213-Günlük!F182 -> 6995.2936 | I8: =Günlük!G213-Günlük!G182 -> 6421.2703 | J8: =Günlük!H213-Günlük!H182 -> 8142.503 | K8: =Günlük!F213 -> 168094.01 | L8: =Günlük!G213 -> 196186.44 | M8: =Günlük!H213 -> 226090.33
A9: Ağustos 2026 | B9: =Günlük!A214 -> 46235 | C9: =Günlük!A244 -> 46265 | D9: 31 | E9: =Günlük!F244/Günlük!F213-1 -> 0.10169087 | F9: =Günlük!G244/Günlük!G213-1 -> 0.087585553 | G9: =Günlük!H244/Günlük!H213-1 -> 0.11947037 | H9: =Günlük!F244-Günlük!F213 -> 17093.627 | I9: =Günlük!G244-Günlük!G213 -> 17183.098 | J9: =Günlük!H244-Günlük!H213 -> 27011.096 | K9: =Günlük!F244 -> 185187.64 | L9: =Günlük!G244 -> 213369.53 | M9: =Günlük!H244 -> 253101.43
A10: Eylül 2026 | B10: =Günlük!A245 -> 46266 | C10: =Günlük!A274 -> 46295 | D10: 30 | E10: =Günlük!F274/Günlük!F244-1 -> 0.11904179 | F10: =Günlük!G274/Günlük!G244-1 -> 0.10924481 | G10: =Günlük!H274/Günlük!H244-1 -> 0.16329644 | H10: =Günlük!F274-Günlük!F244 -> 22045.068 | I10: =Günlük!G274-Günlük!G244 -> 23309.513 | J10: =Günlük!H274-Günlük!H244 -> 41330.562 | K10: =Günlük!F274 -> 207232.71 | L10: =Günlük!G274 -> 236679.05 | M10: =Günlük!H274 -> 294431.99
